2019-06-04 06:31:58,418 ERROR: HTTP_STATUS_CODE_500: {'message': 'Internal Server Error.', 'code': 500} [in api_error_handler:/home/vuns/Desktop/flask-project-master/app/exception.py:191]
Traceback (most recent call last):
  File "/usr/local/lib/python2.7/dist-packages/flask/app.py", line 1832, in full_dispatch_request
    rv = self.dispatch_request()
  File "/usr/local/lib/python2.7/dist-packages/flask/app.py", line 1818, in dispatch_request
    return self.view_functions[rule.endpoint](**req.view_args)
  File "/home/vuns/Desktop/flask-project-master/app/api/chicken_farm_control.py", line 34, in get_feeding_history
    all_history = history_collection.find({})
  File "/home/vuns/Desktop/flask-project-master/app/db/mongo.py", line 19, in find
    return self.db.find(spec=spec, field=field, limit=limit, skip=skip, sort=sort)
  File "/usr/local/lib/python2.7/dist-packages/pymongo/collection.py", line 1456, in find
    return Cursor(self, *args, **kwargs)
TypeError: __init__() got an unexpected keyword argument 'field'
2019-06-04 06:33:37,763 INFO: Config filename: app/config.py [in config_log_handler:/home/vuns/Desktop/flask-project-master/app/app.py:102]
2019-06-04 06:33:37,765 INFO: App log folder: /home/vuns/Desktop/flask-project-master/app/logs [in config_log_handler:/home/vuns/Desktop/flask-project-master/app/app.py:103]
2019-06-04 06:33:40,186 ERROR: HTTP_STATUS_CODE_500: {'message': 'Internal Server Error.', 'code': 500} [in api_error_handler:/home/vuns/Desktop/flask-project-master/app/exception.py:191]
Traceback (most recent call last):
  File "/usr/local/lib/python2.7/dist-packages/flask/app.py", line 1832, in full_dispatch_request
    rv = self.dispatch_request()
  File "/usr/local/lib/python2.7/dist-packages/flask/app.py", line 1818, in dispatch_request
    return self.view_functions[rule.endpoint](**req.view_args)
  File "/home/vuns/Desktop/flask-project-master/app/api/chicken_farm_control.py", line 34, in get_feeding_history
    all_history = history_collection.find({})
  File "/home/vuns/Desktop/flask-project-master/app/db/mongo.py", line 19, in find
    return self.db.find(spec=spec, field=field, limit=limit, skip=skip, sort=sort)
  File "/usr/local/lib/python2.7/dist-packages/pymongo/collection.py", line 1456, in find
    return Cursor(self, *args, **kwargs)
TypeError: __init__() got an unexpected keyword argument 'field'
2019-06-04 06:33:40,186 ERROR: HTTP_STATUS_CODE_500: {'message': 'Internal Server Error.', 'code': 500} [in api_error_handler:/home/vuns/Desktop/flask-project-master/app/exception.py:191]
Traceback (most recent call last):
  File "/usr/local/lib/python2.7/dist-packages/flask/app.py", line 1832, in full_dispatch_request
    rv = self.dispatch_request()
  File "/usr/local/lib/python2.7/dist-packages/flask/app.py", line 1818, in dispatch_request
    return self.view_functions[rule.endpoint](**req.view_args)
  File "/home/vuns/Desktop/flask-project-master/app/api/chicken_farm_control.py", line 34, in get_feeding_history
    all_history = history_collection.find({})
  File "/home/vuns/Desktop/flask-project-master/app/db/mongo.py", line 19, in find
    return self.db.find(spec=spec, field=field, limit=limit, skip=skip, sort=sort)
  File "/usr/local/lib/python2.7/dist-packages/pymongo/collection.py", line 1456, in find
    return Cursor(self, *args, **kwargs)
TypeError: __init__() got an unexpected keyword argument 'field'
2019-06-04 06:35:30,469 INFO: Config filename: app/config.py [in config_log_handler:/home/vuns/Desktop/flask-project-master/app/app.py:102]
2019-06-04 06:35:30,470 INFO: App log folder: /home/vuns/Desktop/flask-project-master/app/logs [in config_log_handler:/home/vuns/Desktop/flask-project-master/app/app.py:103]
2019-06-04 06:35:41,444 INFO: Config filename: app/config.py [in config_log_handler:/home/vuns/Desktop/flask-project-master/app/app.py:102]
2019-06-04 06:35:41,445 INFO: App log folder: /home/vuns/Desktop/flask-project-master/app/logs [in config_log_handler:/home/vuns/Desktop/flask-project-master/app/app.py:103]
2019-06-04 06:35:43,327 ERROR: HTTP_STATUS_CODE_500: {'message': 'Internal Server Error.', 'code': 500} [in api_error_handler:/home/vuns/Desktop/flask-project-master/app/exception.py:191]
Traceback (most recent call last):
  File "/usr/local/lib/python2.7/dist-packages/flask/app.py", line 1832, in full_dispatch_request
    rv = self.dispatch_request()
  File "/usr/local/lib/python2.7/dist-packages/flask/app.py", line 1818, in dispatch_request
    return self.view_functions[rule.endpoint](**req.view_args)
  File "/home/vuns/Desktop/flask-project-master/app/api/chicken_farm_control.py", line 34, in get_feeding_history
    all_history = history_collection.find({})
  File "/home/vuns/Desktop/flask-project-master/app/db/mongo.py", line 19, in find
    return self.db.find(spec=spec, field=field, limit=limit, skip=skip, sort=sort)
  File "/usr/local/lib/python2.7/dist-packages/pymongo/collection.py", line 1456, in find
    return Cursor(self, *args, **kwargs)
TypeError: __init__() got an unexpected keyword argument 'field'
2019-06-04 06:35:43,327 ERROR: HTTP_STATUS_CODE_500: {'message': 'Internal Server Error.', 'code': 500} [in api_error_handler:/home/vuns/Desktop/flask-project-master/app/exception.py:191]
Traceback (most recent call last):
  File "/usr/local/lib/python2.7/dist-packages/flask/app.py", line 1832, in full_dispatch_request
    rv = self.dispatch_request()
  File "/usr/local/lib/python2.7/dist-packages/flask/app.py", line 1818, in dispatch_request
    return self.view_functions[rule.endpoint](**req.view_args)
  File "/home/vuns/Desktop/flask-project-master/app/api/chicken_farm_control.py", line 34, in get_feeding_history
    all_history = history_collection.find({})
  File "/home/vuns/Desktop/flask-project-master/app/db/mongo.py", line 19, in find
    return self.db.find(spec=spec, field=field, limit=limit, skip=skip, sort=sort)
  File "/usr/local/lib/python2.7/dist-packages/pymongo/collection.py", line 1456, in find
    return Cursor(self, *args, **kwargs)
TypeError: __init__() got an unexpected keyword argument 'field'
2019-06-04 06:35:44,541 ERROR: HTTP_STATUS_CODE_500: {'message': 'Internal Server Error.', 'code': 500} [in api_error_handler:/home/vuns/Desktop/flask-project-master/app/exception.py:191]
Traceback (most recent call last):
  File "/usr/local/lib/python2.7/dist-packages/flask/app.py", line 1832, in full_dispatch_request
    rv = self.dispatch_request()
  File "/usr/local/lib/python2.7/dist-packages/flask/app.py", line 1818, in dispatch_request
    return self.view_functions[rule.endpoint](**req.view_args)
  File "/home/vuns/Desktop/flask-project-master/app/api/chicken_farm_control.py", line 34, in get_feeding_history
    all_history = history_collection.find({})
  File "/home/vuns/Desktop/flask-project-master/app/db/mongo.py", line 19, in find
    return self.db.find(spec=spec, field=field, limit=limit, skip=skip, sort=sort)
  File "/usr/local/lib/python2.7/dist-packages/pymongo/collection.py", line 1456, in find
    return Cursor(self, *args, **kwargs)
TypeError: __init__() got an unexpected keyword argument 'field'
2019-06-04 06:35:44,541 ERROR: HTTP_STATUS_CODE_500: {'message': 'Internal Server Error.', 'code': 500} [in api_error_handler:/home/vuns/Desktop/flask-project-master/app/exception.py:191]
Traceback (most recent call last):
  File "/usr/local/lib/python2.7/dist-packages/flask/app.py", line 1832, in full_dispatch_request
    rv = self.dispatch_request()
  File "/usr/local/lib/python2.7/dist-packages/flask/app.py", line 1818, in dispatch_request
    return self.view_functions[rule.endpoint](**req.view_args)
  File "/home/vuns/Desktop/flask-project-master/app/api/chicken_farm_control.py", line 34, in get_feeding_history
    all_history = history_collection.find({})
  File "/home/vuns/Desktop/flask-project-master/app/db/mongo.py", line 19, in find
    return self.db.find(spec=spec, field=field, limit=limit, skip=skip, sort=sort)
  File "/usr/local/lib/python2.7/dist-packages/pymongo/collection.py", line 1456, in find
    return Cursor(self, *args, **kwargs)
TypeError: __init__() got an unexpected keyword argument 'field'
2019-06-04 06:36:31,325 INFO: Config filename: app/config.py [in config_log_handler:/home/vuns/Desktop/flask-project-master/app/app.py:102]
2019-06-04 06:36:31,326 INFO: App log folder: /home/vuns/Desktop/flask-project-master/app/logs [in config_log_handler:/home/vuns/Desktop/flask-project-master/app/app.py:103]
2019-06-04 06:39:14,880 ERROR: HTTP_STATUS_CODE_500: {'message': 'Internal Server Error.', 'code': 500} [in api_error_handler:/home/vuns/Desktop/flask-project-master/app/exception.py:191]
Traceback (most recent call last):
  File "/usr/local/lib/python2.7/dist-packages/flask/app.py", line 1832, in full_dispatch_request
    rv = self.dispatch_request()
  File "/usr/local/lib/python2.7/dist-packages/flask/app.py", line 1818, in dispatch_request
    return self.view_functions[rule.endpoint](**req.view_args)
  File "/home/vuns/Desktop/flask-project-master/app/api/chicken_farm_control.py", line 34, in get_feeding_history
    all_history = history_collection.find({})
  File "/home/vuns/Desktop/flask-project-master/app/db/mongo.py", line 19, in find
    return self.db.find(spec=spec, field=field, limit=limit, skip=skip, sort=sort)
  File "/usr/local/lib/python2.7/dist-packages/pymongo/collection.py", line 1456, in find
    return Cursor(self, *args, **kwargs)
TypeError: __init__() got an unexpected keyword argument 'field'
2019-06-04 06:39:14,880 ERROR: HTTP_STATUS_CODE_500: {'message': 'Internal Server Error.', 'code': 500} [in api_error_handler:/home/vuns/Desktop/flask-project-master/app/exception.py:191]
Traceback (most recent call last):
  File "/usr/local/lib/python2.7/dist-packages/flask/app.py", line 1832, in full_dispatch_request
    rv = self.dispatch_request()
  File "/usr/local/lib/python2.7/dist-packages/flask/app.py", line 1818, in dispatch_request
    return self.view_functions[rule.endpoint](**req.view_args)
  File "/home/vuns/Desktop/flask-project-master/app/api/chicken_farm_control.py", line 34, in get_feeding_history
    all_history = history_collection.find({})
  File "/home/vuns/Desktop/flask-project-master/app/db/mongo.py", line 19, in find
    return self.db.find(spec=spec, field=field, limit=limit, skip=skip, sort=sort)
  File "/usr/local/lib/python2.7/dist-packages/pymongo/collection.py", line 1456, in find
    return Cursor(self, *args, **kwargs)
TypeError: __init__() got an unexpected keyword argument 'field'
2019-06-04 06:40:36,332 INFO: Config filename: app/config.py [in config_log_handler:/home/vuns/Desktop/flask-project-master/app/app.py:102]
2019-06-04 06:40:36,333 INFO: App log folder: /home/vuns/Desktop/flask-project-master/app/logs [in config_log_handler:/home/vuns/Desktop/flask-project-master/app/app.py:103]
2019-06-04 06:40:46,548 INFO: Config filename: app/config.py [in config_log_handler:/home/vuns/Desktop/flask-project-master/app/app.py:102]
2019-06-04 06:40:46,550 INFO: App log folder: /home/vuns/Desktop/flask-project-master/app/logs [in config_log_handler:/home/vuns/Desktop/flask-project-master/app/app.py:103]
2019-06-04 06:40:52,059 ERROR: HTTP_STATUS_CODE_500: {'message': 'Internal Server Error.', 'code': 500} [in api_error_handler:/home/vuns/Desktop/flask-project-master/app/exception.py:191]
Traceback (most recent call last):
  File "/usr/local/lib/python2.7/dist-packages/flask/app.py", line 1832, in full_dispatch_request
    rv = self.dispatch_request()
  File "/usr/local/lib/python2.7/dist-packages/flask/app.py", line 1818, in dispatch_request
    return self.view_functions[rule.endpoint](**req.view_args)
  File "/home/vuns/Desktop/flask-project-master/app/api/chicken_farm_control.py", line 34, in get_feeding_history
    all_history = history_collection.find(spec={})
  File "/home/vuns/Desktop/flask-project-master/app/db/mongo.py", line 19, in find
    return self.db.find(spec=spec, field=field, limit=limit, skip=skip, sort=sort)
  File "/usr/local/lib/python2.7/dist-packages/pymongo/collection.py", line 1456, in find
    return Cursor(self, *args, **kwargs)
TypeError: __init__() got an unexpected keyword argument 'field'
2019-06-04 06:40:52,059 ERROR: HTTP_STATUS_CODE_500: {'message': 'Internal Server Error.', 'code': 500} [in api_error_handler:/home/vuns/Desktop/flask-project-master/app/exception.py:191]
Traceback (most recent call last):
  File "/usr/local/lib/python2.7/dist-packages/flask/app.py", line 1832, in full_dispatch_request
    rv = self.dispatch_request()
  File "/usr/local/lib/python2.7/dist-packages/flask/app.py", line 1818, in dispatch_request
    return self.view_functions[rule.endpoint](**req.view_args)
  File "/home/vuns/Desktop/flask-project-master/app/api/chicken_farm_control.py", line 34, in get_feeding_history
    all_history = history_collection.find(spec={})
  File "/home/vuns/Desktop/flask-project-master/app/db/mongo.py", line 19, in find
    return self.db.find(spec=spec, field=field, limit=limit, skip=skip, sort=sort)
  File "/usr/local/lib/python2.7/dist-packages/pymongo/collection.py", line 1456, in find
    return Cursor(self, *args, **kwargs)
TypeError: __init__() got an unexpected keyword argument 'field'
2019-06-04 06:41:20,000 INFO: Config filename: app/config.py [in config_log_handler:/home/vuns/Desktop/flask-project-master/app/app.py:102]
2019-06-04 06:41:20,001 INFO: App log folder: /home/vuns/Desktop/flask-project-master/app/logs [in config_log_handler:/home/vuns/Desktop/flask-project-master/app/app.py:103]
2019-06-04 06:41:28,500 ERROR: HTTP_STATUS_CODE_500: {'message': 'Internal Server Error.', 'code': 500} [in api_error_handler:/home/vuns/Desktop/flask-project-master/app/exception.py:191]
Traceback (most recent call last):
  File "/usr/local/lib/python2.7/dist-packages/flask/app.py", line 1832, in full_dispatch_request
    rv = self.dispatch_request()
  File "/usr/local/lib/python2.7/dist-packages/flask/app.py", line 1818, in dispatch_request
    return self.view_functions[rule.endpoint](**req.view_args)
  File "/home/vuns/Desktop/flask-project-master/app/api/chicken_farm_control.py", line 34, in get_feeding_history
    all_history = history_collection.find(spec={})
  File "/home/vuns/Desktop/flask-project-master/app/db/mongo.py", line 19, in find
    return self.db.find(spec=spec, field=field, limit=limit, skip=skip, sort=sort)
  File "/usr/local/lib/python2.7/dist-packages/pymongo/collection.py", line 1456, in find
    return Cursor(self, *args, **kwargs)
TypeError: __init__() got an unexpected keyword argument 'field'
2019-06-04 06:41:28,500 ERROR: HTTP_STATUS_CODE_500: {'message': 'Internal Server Error.', 'code': 500} [in api_error_handler:/home/vuns/Desktop/flask-project-master/app/exception.py:191]
Traceback (most recent call last):
  File "/usr/local/lib/python2.7/dist-packages/flask/app.py", line 1832, in full_dispatch_request
    rv = self.dispatch_request()
  File "/usr/local/lib/python2.7/dist-packages/flask/app.py", line 1818, in dispatch_request
    return self.view_functions[rule.endpoint](**req.view_args)
  File "/home/vuns/Desktop/flask-project-master/app/api/chicken_farm_control.py", line 34, in get_feeding_history
    all_history = history_collection.find(spec={})
  File "/home/vuns/Desktop/flask-project-master/app/db/mongo.py", line 19, in find
    return self.db.find(spec=spec, field=field, limit=limit, skip=skip, sort=sort)
  File "/usr/local/lib/python2.7/dist-packages/pymongo/collection.py", line 1456, in find
    return Cursor(self, *args, **kwargs)
TypeError: __init__() got an unexpected keyword argument 'field'
2019-06-04 06:44:56,366 INFO: Config filename: app/config.py [in config_log_handler:/home/vuns/Desktop/flask-project-master/app/app.py:102]
2019-06-04 06:44:56,368 INFO: App log folder: /home/vuns/Desktop/flask-project-master/app/logs [in config_log_handler:/home/vuns/Desktop/flask-project-master/app/app.py:103]
2019-06-04 06:44:59,269 ERROR: HTTP_STATUS_CODE_500: {'message': 'Internal Server Error.', 'code': 500} [in api_error_handler:/home/vuns/Desktop/flask-project-master/app/exception.py:191]
Traceback (most recent call last):
  File "/usr/local/lib/python2.7/dist-packages/flask/app.py", line 1832, in full_dispatch_request
    rv = self.dispatch_request()
  File "/usr/local/lib/python2.7/dist-packages/flask/app.py", line 1818, in dispatch_request
    return self.view_functions[rule.endpoint](**req.view_args)
  File "/home/vuns/Desktop/flask-project-master/app/api/chicken_farm_control.py", line 36, in get_feeding_history
    return jsonify({'history': all_history})
  File "/usr/local/lib/python2.7/dist-packages/flask/json/__init__.py", line 351, in jsonify
    dumps(data, indent=indent, separators=separators) + '\n',
  File "/usr/local/lib/python2.7/dist-packages/flask/json/__init__.py", line 194, in dumps
    rv = _json.dumps(obj, **kwargs)
  File "/usr/local/lib/python2.7/dist-packages/simplejson/__init__.py", line 399, in dumps
    **kw).encode(obj)
  File "/usr/local/lib/python2.7/dist-packages/simplejson/encoder.py", line 298, in encode
    chunks = list(chunks)
  File "/usr/local/lib/python2.7/dist-packages/simplejson/encoder.py", line 696, in _iterencode
    for chunk in _iterencode_dict(o, _current_indent_level):
  File "/usr/local/lib/python2.7/dist-packages/simplejson/encoder.py", line 652, in _iterencode_dict
    for chunk in chunks:
  File "/usr/local/lib/python2.7/dist-packages/simplejson/encoder.py", line 652, in _iterencode_dict
    for chunk in chunks:
  File "/usr/local/lib/python2.7/dist-packages/simplejson/encoder.py", line 716, in _iterencode
    o = _default(o)
  File "/usr/local/lib/python2.7/dist-packages/flask/json/__init__.py", line 81, in default
    return _json.JSONEncoder.default(self, o)
  File "/usr/local/lib/python2.7/dist-packages/simplejson/encoder.py", line 273, in default
    o.__class__.__name__)
TypeError: Object of type ObjectId is not JSON serializable
2019-06-04 06:44:59,269 ERROR: HTTP_STATUS_CODE_500: {'message': 'Internal Server Error.', 'code': 500} [in api_error_handler:/home/vuns/Desktop/flask-project-master/app/exception.py:191]
Traceback (most recent call last):
  File "/usr/local/lib/python2.7/dist-packages/flask/app.py", line 1832, in full_dispatch_request
    rv = self.dispatch_request()
  File "/usr/local/lib/python2.7/dist-packages/flask/app.py", line 1818, in dispatch_request
    return self.view_functions[rule.endpoint](**req.view_args)
  File "/home/vuns/Desktop/flask-project-master/app/api/chicken_farm_control.py", line 36, in get_feeding_history
    return jsonify({'history': all_history})
  File "/usr/local/lib/python2.7/dist-packages/flask/json/__init__.py", line 351, in jsonify
    dumps(data, indent=indent, separators=separators) + '\n',
  File "/usr/local/lib/python2.7/dist-packages/flask/json/__init__.py", line 194, in dumps
    rv = _json.dumps(obj, **kwargs)
  File "/usr/local/lib/python2.7/dist-packages/simplejson/__init__.py", line 399, in dumps
    **kw).encode(obj)
  File "/usr/local/lib/python2.7/dist-packages/simplejson/encoder.py", line 298, in encode
    chunks = list(chunks)
  File "/usr/local/lib/python2.7/dist-packages/simplejson/encoder.py", line 696, in _iterencode
    for chunk in _iterencode_dict(o, _current_indent_level):
  File "/usr/local/lib/python2.7/dist-packages/simplejson/encoder.py", line 652, in _iterencode_dict
    for chunk in chunks:
  File "/usr/local/lib/python2.7/dist-packages/simplejson/encoder.py", line 652, in _iterencode_dict
    for chunk in chunks:
  File "/usr/local/lib/python2.7/dist-packages/simplejson/encoder.py", line 716, in _iterencode
    o = _default(o)
  File "/usr/local/lib/python2.7/dist-packages/flask/json/__init__.py", line 81, in default
    return _json.JSONEncoder.default(self, o)
  File "/usr/local/lib/python2.7/dist-packages/simplejson/encoder.py", line 273, in default
    o.__class__.__name__)
TypeError: Object of type ObjectId is not JSON serializable
2019-06-04 06:45:02,003 ERROR: HTTP_STATUS_CODE_500: {'message': 'Internal Server Error.', 'code': 500} [in api_error_handler:/home/vuns/Desktop/flask-project-master/app/exception.py:191]
Traceback (most recent call last):
  File "/usr/local/lib/python2.7/dist-packages/flask/app.py", line 1832, in full_dispatch_request
    rv = self.dispatch_request()
  File "/usr/local/lib/python2.7/dist-packages/flask/app.py", line 1818, in dispatch_request
    return self.view_functions[rule.endpoint](**req.view_args)
  File "/home/vuns/Desktop/flask-project-master/app/api/chicken_farm_control.py", line 36, in get_feeding_history
    return jsonify({'history': all_history})
  File "/usr/local/lib/python2.7/dist-packages/flask/json/__init__.py", line 351, in jsonify
    dumps(data, indent=indent, separators=separators) + '\n',
  File "/usr/local/lib/python2.7/dist-packages/flask/json/__init__.py", line 194, in dumps
    rv = _json.dumps(obj, **kwargs)
  File "/usr/local/lib/python2.7/dist-packages/simplejson/__init__.py", line 399, in dumps
    **kw).encode(obj)
  File "/usr/local/lib/python2.7/dist-packages/simplejson/encoder.py", line 298, in encode
    chunks = list(chunks)
  File "/usr/local/lib/python2.7/dist-packages/simplejson/encoder.py", line 696, in _iterencode
    for chunk in _iterencode_dict(o, _current_indent_level):
  File "/usr/local/lib/python2.7/dist-packages/simplejson/encoder.py", line 652, in _iterencode_dict
    for chunk in chunks:
  File "/usr/local/lib/python2.7/dist-packages/simplejson/encoder.py", line 652, in _iterencode_dict
    for chunk in chunks:
  File "/usr/local/lib/python2.7/dist-packages/simplejson/encoder.py", line 716, in _iterencode
    o = _default(o)
  File "/usr/local/lib/python2.7/dist-packages/flask/json/__init__.py", line 81, in default
    return _json.JSONEncoder.default(self, o)
  File "/usr/local/lib/python2.7/dist-packages/simplejson/encoder.py", line 273, in default
    o.__class__.__name__)
TypeError: Object of type ObjectId is not JSON serializable
2019-06-04 06:45:02,003 ERROR: HTTP_STATUS_CODE_500: {'message': 'Internal Server Error.', 'code': 500} [in api_error_handler:/home/vuns/Desktop/flask-project-master/app/exception.py:191]
Traceback (most recent call last):
  File "/usr/local/lib/python2.7/dist-packages/flask/app.py", line 1832, in full_dispatch_request
    rv = self.dispatch_request()
  File "/usr/local/lib/python2.7/dist-packages/flask/app.py", line 1818, in dispatch_request
    return self.view_functions[rule.endpoint](**req.view_args)
  File "/home/vuns/Desktop/flask-project-master/app/api/chicken_farm_control.py", line 36, in get_feeding_history
    return jsonify({'history': all_history})
  File "/usr/local/lib/python2.7/dist-packages/flask/json/__init__.py", line 351, in jsonify
    dumps(data, indent=indent, separators=separators) + '\n',
  File "/usr/local/lib/python2.7/dist-packages/flask/json/__init__.py", line 194, in dumps
    rv = _json.dumps(obj, **kwargs)
  File "/usr/local/lib/python2.7/dist-packages/simplejson/__init__.py", line 399, in dumps
    **kw).encode(obj)
  File "/usr/local/lib/python2.7/dist-packages/simplejson/encoder.py", line 298, in encode
    chunks = list(chunks)
  File "/usr/local/lib/python2.7/dist-packages/simplejson/encoder.py", line 696, in _iterencode
    for chunk in _iterencode_dict(o, _current_indent_level):
  File "/usr/local/lib/python2.7/dist-packages/simplejson/encoder.py", line 652, in _iterencode_dict
    for chunk in chunks:
  File "/usr/local/lib/python2.7/dist-packages/simplejson/encoder.py", line 652, in _iterencode_dict
    for chunk in chunks:
  File "/usr/local/lib/python2.7/dist-packages/simplejson/encoder.py", line 716, in _iterencode
    o = _default(o)
  File "/usr/local/lib/python2.7/dist-packages/flask/json/__init__.py", line 81, in default
    return _json.JSONEncoder.default(self, o)
  File "/usr/local/lib/python2.7/dist-packages/simplejson/encoder.py", line 273, in default
    o.__class__.__name__)
TypeError: Object of type ObjectId is not JSON serializable
2019-06-04 06:49:24,473 ERROR: HTTP_STATUS_CODE_500: {'message': 'Internal Server Error.', 'code': 500} [in api_error_handler:/home/vuns/Desktop/flask-project-master/app/exception.py:191]
Traceback (most recent call last):
  File "/usr/local/lib/python2.7/dist-packages/flask/app.py", line 1832, in full_dispatch_request
    rv = self.dispatch_request()
  File "/usr/local/lib/python2.7/dist-packages/flask/app.py", line 1818, in dispatch_request
    return self.view_functions[rule.endpoint](**req.view_args)
  File "/home/vuns/Desktop/flask-project-master/app/api/chicken_farm_control.py", line 36, in get_feeding_history
    return jsonify({'history': all_history})
  File "/usr/local/lib/python2.7/dist-packages/flask/json/__init__.py", line 351, in jsonify
    dumps(data, indent=indent, separators=separators) + '\n',
  File "/usr/local/lib/python2.7/dist-packages/flask/json/__init__.py", line 194, in dumps
    rv = _json.dumps(obj, **kwargs)
  File "/usr/local/lib/python2.7/dist-packages/simplejson/__init__.py", line 399, in dumps
    **kw).encode(obj)
  File "/usr/local/lib/python2.7/dist-packages/simplejson/encoder.py", line 298, in encode
    chunks = list(chunks)
  File "/usr/local/lib/python2.7/dist-packages/simplejson/encoder.py", line 696, in _iterencode
    for chunk in _iterencode_dict(o, _current_indent_level):
  File "/usr/local/lib/python2.7/dist-packages/simplejson/encoder.py", line 652, in _iterencode_dict
    for chunk in chunks:
  File "/usr/local/lib/python2.7/dist-packages/simplejson/encoder.py", line 652, in _iterencode_dict
    for chunk in chunks:
  File "/usr/local/lib/python2.7/dist-packages/simplejson/encoder.py", line 716, in _iterencode
    o = _default(o)
  File "/usr/local/lib/python2.7/dist-packages/flask/json/__init__.py", line 81, in default
    return _json.JSONEncoder.default(self, o)
  File "/usr/local/lib/python2.7/dist-packages/simplejson/encoder.py", line 273, in default
    o.__class__.__name__)
TypeError: Object of type ObjectId is not JSON serializable
2019-06-04 06:49:24,473 ERROR: HTTP_STATUS_CODE_500: {'message': 'Internal Server Error.', 'code': 500} [in api_error_handler:/home/vuns/Desktop/flask-project-master/app/exception.py:191]
Traceback (most recent call last):
  File "/usr/local/lib/python2.7/dist-packages/flask/app.py", line 1832, in full_dispatch_request
    rv = self.dispatch_request()
  File "/usr/local/lib/python2.7/dist-packages/flask/app.py", line 1818, in dispatch_request
    return self.view_functions[rule.endpoint](**req.view_args)
  File "/home/vuns/Desktop/flask-project-master/app/api/chicken_farm_control.py", line 36, in get_feeding_history
    return jsonify({'history': all_history})
  File "/usr/local/lib/python2.7/dist-packages/flask/json/__init__.py", line 351, in jsonify
    dumps(data, indent=indent, separators=separators) + '\n',
  File "/usr/local/lib/python2.7/dist-packages/flask/json/__init__.py", line 194, in dumps
    rv = _json.dumps(obj, **kwargs)
  File "/usr/local/lib/python2.7/dist-packages/simplejson/__init__.py", line 399, in dumps
    **kw).encode(obj)
  File "/usr/local/lib/python2.7/dist-packages/simplejson/encoder.py", line 298, in encode
    chunks = list(chunks)
  File "/usr/local/lib/python2.7/dist-packages/simplejson/encoder.py", line 696, in _iterencode
    for chunk in _iterencode_dict(o, _current_indent_level):
  File "/usr/local/lib/python2.7/dist-packages/simplejson/encoder.py", line 652, in _iterencode_dict
    for chunk in chunks:
  File "/usr/local/lib/python2.7/dist-packages/simplejson/encoder.py", line 652, in _iterencode_dict
    for chunk in chunks:
  File "/usr/local/lib/python2.7/dist-packages/simplejson/encoder.py", line 716, in _iterencode
    o = _default(o)
  File "/usr/local/lib/python2.7/dist-packages/flask/json/__init__.py", line 81, in default
    return _json.JSONEncoder.default(self, o)
  File "/usr/local/lib/python2.7/dist-packages/simplejson/encoder.py", line 273, in default
    o.__class__.__name__)
TypeError: Object of type ObjectId is not JSON serializable
2019-06-04 06:49:39,887 INFO: Config filename: app/config.py [in config_log_handler:/home/vuns/Desktop/flask-project-master/app/app.py:102]
2019-06-04 06:49:39,888 INFO: App log folder: /home/vuns/Desktop/flask-project-master/app/logs [in config_log_handler:/home/vuns/Desktop/flask-project-master/app/app.py:103]
2019-06-04 06:49:43,029 ERROR: HTTP_STATUS_CODE_500: {'message': 'Internal Server Error.', 'code': 500} [in api_error_handler:/home/vuns/Desktop/flask-project-master/app/exception.py:191]
Traceback (most recent call last):
  File "/usr/local/lib/python2.7/dist-packages/flask/app.py", line 1832, in full_dispatch_request
    rv = self.dispatch_request()
  File "/usr/local/lib/python2.7/dist-packages/flask/app.py", line 1818, in dispatch_request
    return self.view_functions[rule.endpoint](**req.view_args)
  File "/home/vuns/Desktop/flask-project-master/app/api/chicken_farm_control.py", line 34, in get_feeding_history
    all_history = history_collection.find()
TypeError: find() takes at least 2 arguments (1 given)
2019-06-04 06:49:43,029 ERROR: HTTP_STATUS_CODE_500: {'message': 'Internal Server Error.', 'code': 500} [in api_error_handler:/home/vuns/Desktop/flask-project-master/app/exception.py:191]
Traceback (most recent call last):
  File "/usr/local/lib/python2.7/dist-packages/flask/app.py", line 1832, in full_dispatch_request
    rv = self.dispatch_request()
  File "/usr/local/lib/python2.7/dist-packages/flask/app.py", line 1818, in dispatch_request
    return self.view_functions[rule.endpoint](**req.view_args)
  File "/home/vuns/Desktop/flask-project-master/app/api/chicken_farm_control.py", line 34, in get_feeding_history
    all_history = history_collection.find()
TypeError: find() takes at least 2 arguments (1 given)
2019-06-04 06:49:57,342 INFO: Config filename: app/config.py [in config_log_handler:/home/vuns/Desktop/flask-project-master/app/app.py:102]
2019-06-04 06:49:57,342 INFO: App log folder: /home/vuns/Desktop/flask-project-master/app/logs [in config_log_handler:/home/vuns/Desktop/flask-project-master/app/app.py:103]
2019-06-04 06:50:03,670 ERROR: HTTP_STATUS_CODE_500: {'message': 'Internal Server Error.', 'code': 500} [in api_error_handler:/home/vuns/Desktop/flask-project-master/app/exception.py:191]
Traceback (most recent call last):
  File "/usr/local/lib/python2.7/dist-packages/flask/app.py", line 1832, in full_dispatch_request
    rv = self.dispatch_request()
  File "/usr/local/lib/python2.7/dist-packages/flask/app.py", line 1818, in dispatch_request
    return self.view_functions[rule.endpoint](**req.view_args)
  File "/home/vuns/Desktop/flask-project-master/app/api/chicken_farm_control.py", line 34, in get_feeding_history
    all_history = history_collection.find({})
  File "/home/vuns/Desktop/flask-project-master/app/db/mongo.py", line 19, in find
    return self.db.find(spec=spec, field=field, limit=limit, skip=skip, sort=sort)
  File "/usr/local/lib/python2.7/dist-packages/pymongo/collection.py", line 1456, in find
    return Cursor(self, *args, **kwargs)
TypeError: __init__() got an unexpected keyword argument 'field'
2019-06-04 06:50:03,670 ERROR: HTTP_STATUS_CODE_500: {'message': 'Internal Server Error.', 'code': 500} [in api_error_handler:/home/vuns/Desktop/flask-project-master/app/exception.py:191]
Traceback (most recent call last):
  File "/usr/local/lib/python2.7/dist-packages/flask/app.py", line 1832, in full_dispatch_request
    rv = self.dispatch_request()
  File "/usr/local/lib/python2.7/dist-packages/flask/app.py", line 1818, in dispatch_request
    return self.view_functions[rule.endpoint](**req.view_args)
  File "/home/vuns/Desktop/flask-project-master/app/api/chicken_farm_control.py", line 34, in get_feeding_history
    all_history = history_collection.find({})
  File "/home/vuns/Desktop/flask-project-master/app/db/mongo.py", line 19, in find
    return self.db.find(spec=spec, field=field, limit=limit, skip=skip, sort=sort)
  File "/usr/local/lib/python2.7/dist-packages/pymongo/collection.py", line 1456, in find
    return Cursor(self, *args, **kwargs)
TypeError: __init__() got an unexpected keyword argument 'field'
2019-06-04 15:19:39,406 INFO: Config filename: app/config.py [in config_log_handler:/home/vuns/Desktop/flask-project-master/app/app.py:102]
2019-06-04 15:19:39,560 INFO: App log folder: /home/vuns/Desktop/flask-project-master/app/logs [in config_log_handler:/home/vuns/Desktop/flask-project-master/app/app.py:103]
2019-06-04 15:21:32,290 ERROR: HTTP_STATUS_CODE_500: {'message': 'Internal Server Error.', 'code': 500} [in api_error_handler:/home/vuns/Desktop/flask-project-master/app/exception.py:191]
Traceback (most recent call last):
  File "/usr/local/lib/python2.7/dist-packages/flask/app.py", line 1832, in full_dispatch_request
    rv = self.dispatch_request()
  File "/usr/local/lib/python2.7/dist-packages/flask/app.py", line 1818, in dispatch_request
    return self.view_functions[rule.endpoint](**req.view_args)
  File "/home/vuns/Desktop/flask-project-master/app/api/chicken_farm_control.py", line 24, in setting
    'settings': fields.List(Setting, required=True)
  File "/usr/local/lib/python2.7/dist-packages/marshmallow/fields.py", line 536, in __init__
    raise ValueError('The type of the list elements '
ValueError: The type of the list elements must be a subclass of marshmallow.base.FieldABC
2019-06-04 15:21:32,290 ERROR: HTTP_STATUS_CODE_500: {'message': 'Internal Server Error.', 'code': 500} [in api_error_handler:/home/vuns/Desktop/flask-project-master/app/exception.py:191]
Traceback (most recent call last):
  File "/usr/local/lib/python2.7/dist-packages/flask/app.py", line 1832, in full_dispatch_request
    rv = self.dispatch_request()
  File "/usr/local/lib/python2.7/dist-packages/flask/app.py", line 1818, in dispatch_request
    return self.view_functions[rule.endpoint](**req.view_args)
  File "/home/vuns/Desktop/flask-project-master/app/api/chicken_farm_control.py", line 24, in setting
    'settings': fields.List(Setting, required=True)
  File "/usr/local/lib/python2.7/dist-packages/marshmallow/fields.py", line 536, in __init__
    raise ValueError('The type of the list elements '
ValueError: The type of the list elements must be a subclass of marshmallow.base.FieldABC
2019-06-04 15:30:46,524 ERROR: HTTP_STATUS_CODE_500: {'message': 'Internal Server Error.', 'code': 500} [in api_error_handler:/home/vuns/Desktop/flask-project-master/app/exception.py:191]
Traceback (most recent call last):
  File "/usr/local/lib/python2.7/dist-packages/flask/app.py", line 1832, in full_dispatch_request
    rv = self.dispatch_request()
  File "/usr/local/lib/python2.7/dist-packages/flask/app.py", line 1818, in dispatch_request
    return self.view_functions[rule.endpoint](**req.view_args)
  File "/home/vuns/Desktop/flask-project-master/app/api/chicken_farm_control.py", line 24, in setting
    'settings': fields.List(Setting, required=True)
  File "/usr/local/lib/python2.7/dist-packages/marshmallow/fields.py", line 536, in __init__
    raise ValueError('The type of the list elements '
ValueError: The type of the list elements must be a subclass of marshmallow.base.FieldABC
2019-06-04 15:30:46,524 ERROR: HTTP_STATUS_CODE_500: {'message': 'Internal Server Error.', 'code': 500} [in api_error_handler:/home/vuns/Desktop/flask-project-master/app/exception.py:191]
Traceback (most recent call last):
  File "/usr/local/lib/python2.7/dist-packages/flask/app.py", line 1832, in full_dispatch_request
    rv = self.dispatch_request()
  File "/usr/local/lib/python2.7/dist-packages/flask/app.py", line 1818, in dispatch_request
    return self.view_functions[rule.endpoint](**req.view_args)
  File "/home/vuns/Desktop/flask-project-master/app/api/chicken_farm_control.py", line 24, in setting
    'settings': fields.List(Setting, required=True)
  File "/usr/local/lib/python2.7/dist-packages/marshmallow/fields.py", line 536, in __init__
    raise ValueError('The type of the list elements '
ValueError: The type of the list elements must be a subclass of marshmallow.base.FieldABC
2019-06-04 15:32:58,204 INFO: Config filename: app/config.py [in config_log_handler:/home/vuns/Desktop/flask-project-master/app/app.py:102]
2019-06-04 15:32:58,206 INFO: App log folder: /home/vuns/Desktop/flask-project-master/app/logs [in config_log_handler:/home/vuns/Desktop/flask-project-master/app/app.py:103]
2019-06-04 15:33:02,298 ERROR: HTTP_STATUS_CODE_422: {'message': None, 'code': 422} [in api_error_handler:/home/vuns/Desktop/flask-project-master/app/exception.py:191]
Traceback (most recent call last):
  File "/usr/local/lib/python2.7/dist-packages/flask/app.py", line 1832, in full_dispatch_request
    rv = self.dispatch_request()
  File "/usr/local/lib/python2.7/dist-packages/flask/app.py", line 1818, in dispatch_request
    return self.view_functions[rule.endpoint](**req.view_args)
  File "/home/vuns/Desktop/flask-project-master/app/api/chicken_farm_control.py", line 26, in setting
    args = parser.parse(params)
  File "/usr/local/lib/python2.7/dist-packages/webargs/core.py", line 370, in parse
    error, req, schema, error_status_code, error_headers
  File "/usr/local/lib/python2.7/dist-packages/webargs/core.py", line 288, in _on_validation_error
    error_handler(error, req, schema, error_status_code, error_headers)
  File "/usr/local/lib/python2.7/dist-packages/webargs/flaskparser.py", line 111, in handle_error
    headers=error_headers,
  File "/usr/local/lib/python2.7/dist-packages/webargs/flaskparser.py", line 40, in abort
    raise err
UnprocessableEntity: 422 Unprocessable Entity: {'message': None, 'code': 422}
2019-06-04 15:33:02,298 ERROR: HTTP_STATUS_CODE_422: {'message': None, 'code': 422} [in api_error_handler:/home/vuns/Desktop/flask-project-master/app/exception.py:191]
Traceback (most recent call last):
  File "/usr/local/lib/python2.7/dist-packages/flask/app.py", line 1832, in full_dispatch_request
    rv = self.dispatch_request()
  File "/usr/local/lib/python2.7/dist-packages/flask/app.py", line 1818, in dispatch_request
    return self.view_functions[rule.endpoint](**req.view_args)
  File "/home/vuns/Desktop/flask-project-master/app/api/chicken_farm_control.py", line 26, in setting
    args = parser.parse(params)
  File "/usr/local/lib/python2.7/dist-packages/webargs/core.py", line 370, in parse
    error, req, schema, error_status_code, error_headers
  File "/usr/local/lib/python2.7/dist-packages/webargs/core.py", line 288, in _on_validation_error
    error_handler(error, req, schema, error_status_code, error_headers)
  File "/usr/local/lib/python2.7/dist-packages/webargs/flaskparser.py", line 111, in handle_error
    headers=error_headers,
  File "/usr/local/lib/python2.7/dist-packages/webargs/flaskparser.py", line 40, in abort
    raise err
UnprocessableEntity: 422 Unprocessable Entity: {'message': None, 'code': 422}
2019-06-04 15:33:31,182 ERROR: HTTP_STATUS_CODE_500: {'message': 'Internal Server Error.', 'code': 500} [in api_error_handler:/home/vuns/Desktop/flask-project-master/app/exception.py:191]
Traceback (most recent call last):
  File "/usr/local/lib/python2.7/dist-packages/flask/app.py", line 1832, in full_dispatch_request
    rv = self.dispatch_request()
  File "/usr/local/lib/python2.7/dist-packages/flask/app.py", line 1818, in dispatch_request
    return self.view_functions[rule.endpoint](**req.view_args)
  File "/home/vuns/Desktop/flask-project-master/app/api/chicken_farm_control.py", line 33, in setting
    settings_collection.insert(data)
TypeError: insert() takes exactly 1 argument (2 given)
2019-06-04 15:33:31,182 ERROR: HTTP_STATUS_CODE_500: {'message': 'Internal Server Error.', 'code': 500} [in api_error_handler:/home/vuns/Desktop/flask-project-master/app/exception.py:191]
Traceback (most recent call last):
  File "/usr/local/lib/python2.7/dist-packages/flask/app.py", line 1832, in full_dispatch_request
    rv = self.dispatch_request()
  File "/usr/local/lib/python2.7/dist-packages/flask/app.py", line 1818, in dispatch_request
    return self.view_functions[rule.endpoint](**req.view_args)
  File "/home/vuns/Desktop/flask-project-master/app/api/chicken_farm_control.py", line 33, in setting
    settings_collection.insert(data)
TypeError: insert() takes exactly 1 argument (2 given)
2019-06-04 15:34:59,367 INFO: Config filename: app/config.py [in config_log_handler:/home/vuns/Desktop/flask-project-master/app/app.py:102]
2019-06-04 15:34:59,369 INFO: App log folder: /home/vuns/Desktop/flask-project-master/app/logs [in config_log_handler:/home/vuns/Desktop/flask-project-master/app/app.py:103]
2019-06-04 15:39:51,864 INFO: Config filename: app/config.py [in config_log_handler:/home/vuns/Desktop/flask-project-master/app/app.py:102]
2019-06-04 15:39:51,866 INFO: App log folder: /home/vuns/Desktop/flask-project-master/app/logs [in config_log_handler:/home/vuns/Desktop/flask-project-master/app/app.py:103]
2019-06-04 15:39:59,646 ERROR: HTTP_STATUS_CODE_500: {'message': 'Internal Server Error.', 'code': 500} [in api_error_handler:/home/vuns/Desktop/flask-project-master/app/exception.py:191]
Traceback (most recent call last):
  File "/usr/local/lib/python2.7/dist-packages/flask/app.py", line 1832, in full_dispatch_request
    rv = self.dispatch_request()
  File "/usr/local/lib/python2.7/dist-packages/flask/app.py", line 1818, in dispatch_request
    return self.view_functions[rule.endpoint](**req.view_args)
  File "/home/vuns/Desktop/flask-project-master/app/api/chicken_farm_control.py", line 33, in setting
    'timestamp': setting['start_time'],
KeyError: 'start_time'
2019-06-04 15:39:59,646 ERROR: HTTP_STATUS_CODE_500: {'message': 'Internal Server Error.', 'code': 500} [in api_error_handler:/home/vuns/Desktop/flask-project-master/app/exception.py:191]
Traceback (most recent call last):
  File "/usr/local/lib/python2.7/dist-packages/flask/app.py", line 1832, in full_dispatch_request
    rv = self.dispatch_request()
  File "/usr/local/lib/python2.7/dist-packages/flask/app.py", line 1818, in dispatch_request
    return self.view_functions[rule.endpoint](**req.view_args)
  File "/home/vuns/Desktop/flask-project-master/app/api/chicken_farm_control.py", line 33, in setting
    'timestamp': setting['start_time'],
KeyError: 'start_time'
2019-06-04 15:41:01,447 INFO: Config filename: app/config.py [in config_log_handler:/home/vuns/Desktop/flask-project-master/app/app.py:102]
2019-06-04 15:41:01,449 INFO: App log folder: /home/vuns/Desktop/flask-project-master/app/logs [in config_log_handler:/home/vuns/Desktop/flask-project-master/app/app.py:103]
2019-06-04 16:00:31,210 INFO: Config filename: app/config.py [in config_log_handler:/home/vuns/Desktop/flask-project-master/app/app.py:101]
2019-06-04 16:00:31,211 INFO: App log folder: /home/vuns/Desktop/flask-project-master/app/logs [in config_log_handler:/home/vuns/Desktop/flask-project-master/app/app.py:102]
2019-06-04 16:05:41,054 INFO: Config filename: app/config.py [in config_log_handler:/home/vuns/Desktop/flask-project-master/app/app.py:101]
2019-06-04 16:05:41,056 INFO: App log folder: /home/vuns/Desktop/flask-project-master/app/logs [in config_log_handler:/home/vuns/Desktop/flask-project-master/app/app.py:102]
2019-06-04 16:05:53,895 ERROR: HTTP_STATUS_CODE_500: {'message': 'Internal Server Error.', 'code': 500} [in api_error_handler:/home/vuns/Desktop/flask-project-master/app/exception.py:191]
Traceback (most recent call last):
  File "/usr/local/lib/python2.7/dist-packages/flask/app.py", line 1832, in full_dispatch_request
    rv = self.dispatch_request()
  File "/usr/local/lib/python2.7/dist-packages/flask/app.py", line 1818, in dispatch_request
    return self.view_functions[rule.endpoint](**req.view_args)
  File "/home/vuns/Desktop/flask-project-master/app/api/chicken_farm_control.py", line 55, in get_feeding_history
    all_history = history_collection.find({})
  File "/home/vuns/Desktop/flask-project-master/app/db/mongo.py", line 19, in find
    return self.db.find(spec=spec, field=field, limit=limit, skip=skip, sort=sort)
  File "/usr/local/lib/python2.7/dist-packages/pymongo/collection.py", line 1456, in find
    return Cursor(self, *args, **kwargs)
TypeError: __init__() got an unexpected keyword argument 'field'
2019-06-04 16:05:53,895 ERROR: HTTP_STATUS_CODE_500: {'message': 'Internal Server Error.', 'code': 500} [in api_error_handler:/home/vuns/Desktop/flask-project-master/app/exception.py:191]
Traceback (most recent call last):
  File "/usr/local/lib/python2.7/dist-packages/flask/app.py", line 1832, in full_dispatch_request
    rv = self.dispatch_request()
  File "/usr/local/lib/python2.7/dist-packages/flask/app.py", line 1818, in dispatch_request
    return self.view_functions[rule.endpoint](**req.view_args)
  File "/home/vuns/Desktop/flask-project-master/app/api/chicken_farm_control.py", line 55, in get_feeding_history
    all_history = history_collection.find({})
  File "/home/vuns/Desktop/flask-project-master/app/db/mongo.py", line 19, in find
    return self.db.find(spec=spec, field=field, limit=limit, skip=skip, sort=sort)
  File "/usr/local/lib/python2.7/dist-packages/pymongo/collection.py", line 1456, in find
    return Cursor(self, *args, **kwargs)
TypeError: __init__() got an unexpected keyword argument 'field'
2019-06-04 16:09:39,574 INFO: Config filename: app/config.py [in config_log_handler:/home/vuns/Desktop/flask-project-master/app/app.py:101]
2019-06-04 16:09:39,575 INFO: App log folder: /home/vuns/Desktop/flask-project-master/app/logs [in config_log_handler:/home/vuns/Desktop/flask-project-master/app/app.py:102]
2019-06-04 16:09:48,204 ERROR: HTTP_STATUS_CODE_500: {'message': 'Internal Server Error.', 'code': 500} [in api_error_handler:/home/vuns/Desktop/flask-project-master/app/exception.py:191]
Traceback (most recent call last):
  File "/usr/local/lib/python2.7/dist-packages/flask/app.py", line 1832, in full_dispatch_request
    rv = self.dispatch_request()
  File "/usr/local/lib/python2.7/dist-packages/flask/app.py", line 1818, in dispatch_request
    return self.view_functions[rule.endpoint](**req.view_args)
  File "/home/vuns/Desktop/flask-project-master/app/api/chicken_farm_control.py", line 55, in get_feeding_history
    all_history = history_collection.find({})
  File "/home/vuns/Desktop/flask-project-master/app/db/mongo.py", line 20, in find
    return self.db.find(spec=spec)
  File "/usr/local/lib/python2.7/dist-packages/pymongo/collection.py", line 1456, in find
    return Cursor(self, *args, **kwargs)
TypeError: __init__() got an unexpected keyword argument 'spec'
2019-06-04 16:09:48,204 ERROR: HTTP_STATUS_CODE_500: {'message': 'Internal Server Error.', 'code': 500} [in api_error_handler:/home/vuns/Desktop/flask-project-master/app/exception.py:191]
Traceback (most recent call last):
  File "/usr/local/lib/python2.7/dist-packages/flask/app.py", line 1832, in full_dispatch_request
    rv = self.dispatch_request()
  File "/usr/local/lib/python2.7/dist-packages/flask/app.py", line 1818, in dispatch_request
    return self.view_functions[rule.endpoint](**req.view_args)
  File "/home/vuns/Desktop/flask-project-master/app/api/chicken_farm_control.py", line 55, in get_feeding_history
    all_history = history_collection.find({})
  File "/home/vuns/Desktop/flask-project-master/app/db/mongo.py", line 20, in find
    return self.db.find(spec=spec)
  File "/usr/local/lib/python2.7/dist-packages/pymongo/collection.py", line 1456, in find
    return Cursor(self, *args, **kwargs)
TypeError: __init__() got an unexpected keyword argument 'spec'
2019-06-04 16:10:28,641 INFO: Config filename: app/config.py [in config_log_handler:/home/vuns/Desktop/flask-project-master/app/app.py:101]
2019-06-04 16:10:28,642 INFO: App log folder: /home/vuns/Desktop/flask-project-master/app/logs [in config_log_handler:/home/vuns/Desktop/flask-project-master/app/app.py:102]
2019-06-04 16:11:17,320 INFO: Config filename: app/config.py [in config_log_handler:/home/vuns/Desktop/flask-project-master/app/app.py:101]
2019-06-04 16:11:17,321 INFO: App log folder: /home/vuns/Desktop/flask-project-master/app/logs [in config_log_handler:/home/vuns/Desktop/flask-project-master/app/app.py:102]
2019-06-04 16:16:25,025 INFO: Config filename: app/config.py [in config_log_handler:/home/vuns/Desktop/flask-project-master/app/app.py:101]
2019-06-04 16:16:25,027 INFO: App log folder: /home/vuns/Desktop/flask-project-master/app/logs [in config_log_handler:/home/vuns/Desktop/flask-project-master/app/app.py:102]
2019-06-05 03:52:07,442 INFO: Config filename: app/config.py [in config_log_handler:/home/vuns/Desktop/flask-project-master/app/app.py:103]
2019-06-05 03:52:07,443 INFO: App log folder: /home/vuns/Desktop/flask-project-master/app/logs [in config_log_handler:/home/vuns/Desktop/flask-project-master/app/app.py:104]
2019-06-05 03:52:56,507 INFO: Config filename: app/config.py [in config_log_handler:/home/vuns/Desktop/flask-project-master/app/app.py:103]
2019-06-05 03:52:56,508 INFO: App log folder: /home/vuns/Desktop/flask-project-master/app/logs [in config_log_handler:/home/vuns/Desktop/flask-project-master/app/app.py:104]
2019-06-05 03:53:23,681 INFO: Config filename: app/config.py [in config_log_handler:/home/vuns/Desktop/flask-project-master/app/app.py:103]
2019-06-05 03:53:23,682 INFO: App log folder: /home/vuns/Desktop/flask-project-master/app/logs [in config_log_handler:/home/vuns/Desktop/flask-project-master/app/app.py:104]
2019-06-05 03:54:40,847 INFO: Config filename: app/config.py [in config_log_handler:/home/vuns/Desktop/flask-project-master/app/app.py:103]
2019-06-05 03:54:40,848 INFO: App log folder: /home/vuns/Desktop/flask-project-master/app/logs [in config_log_handler:/home/vuns/Desktop/flask-project-master/app/app.py:104]
2019-06-05 03:55:40,313 ERROR: HTTP_STATUS_CODE_500: {'message': 'Internal Server Error.', 'code': 500} [in api_error_handler:/home/vuns/Desktop/flask-project-master/app/exception.py:191]
Traceback (most recent call last):
  File "/usr/local/lib/python2.7/dist-packages/flask/app.py", line 1832, in full_dispatch_request
    rv = self.dispatch_request()
  File "/usr/local/lib/python2.7/dist-packages/flask/app.py", line 1818, in dispatch_request
    return self.view_functions[rule.endpoint](**req.view_args)
  File "/home/vuns/Desktop/flask-project-master/app/api/chicken_farm_control.py", line 51, in feeding
    control_feeding(status)
  File "/home/vuns/Desktop/flask-project-master/app/utils/farm_control.py", line 14, in control_feeding
    publish.single(current_app.config['FEEDING_TOPIC'], '0', hostname=current_app.config['MQT_SERVER'])
  File "/usr/local/lib/python2.7/dist-packages/paho/mqtt/publish.py", line 223, in single
    protocol, transport)
  File "/usr/local/lib/python2.7/dist-packages/paho/mqtt/publish.py", line 159, in multiple
    client.connect(hostname, port, keepalive)
  File "/usr/local/lib/python2.7/dist-packages/paho/mqtt/client.py", line 839, in connect
    return self.reconnect()
  File "/usr/local/lib/python2.7/dist-packages/paho/mqtt/client.py", line 962, in reconnect
    sock = socket.create_connection((self._host, self._port), source_address=(self._bind_address, 0))
  File "/usr/lib/python2.7/socket.py", line 575, in create_connection
    raise err
error: [Errno 111] Connection refused
2019-06-05 03:55:40,313 ERROR: HTTP_STATUS_CODE_500: {'message': 'Internal Server Error.', 'code': 500} [in api_error_handler:/home/vuns/Desktop/flask-project-master/app/exception.py:191]
Traceback (most recent call last):
  File "/usr/local/lib/python2.7/dist-packages/flask/app.py", line 1832, in full_dispatch_request
    rv = self.dispatch_request()
  File "/usr/local/lib/python2.7/dist-packages/flask/app.py", line 1818, in dispatch_request
    return self.view_functions[rule.endpoint](**req.view_args)
  File "/home/vuns/Desktop/flask-project-master/app/api/chicken_farm_control.py", line 51, in feeding
    control_feeding(status)
  File "/home/vuns/Desktop/flask-project-master/app/utils/farm_control.py", line 14, in control_feeding
    publish.single(current_app.config['FEEDING_TOPIC'], '0', hostname=current_app.config['MQT_SERVER'])
  File "/usr/local/lib/python2.7/dist-packages/paho/mqtt/publish.py", line 223, in single
    protocol, transport)
  File "/usr/local/lib/python2.7/dist-packages/paho/mqtt/publish.py", line 159, in multiple
    client.connect(hostname, port, keepalive)
  File "/usr/local/lib/python2.7/dist-packages/paho/mqtt/client.py", line 839, in connect
    return self.reconnect()
  File "/usr/local/lib/python2.7/dist-packages/paho/mqtt/client.py", line 962, in reconnect
    sock = socket.create_connection((self._host, self._port), source_address=(self._bind_address, 0))
  File "/usr/lib/python2.7/socket.py", line 575, in create_connection
    raise err
error: [Errno 111] Connection refused
2019-06-05 03:56:03,744 ERROR: HTTP_STATUS_CODE_500: {'message': 'Internal Server Error.', 'code': 500} [in api_error_handler:/home/vuns/Desktop/flask-project-master/app/exception.py:191]
Traceback (most recent call last):
  File "/usr/local/lib/python2.7/dist-packages/flask/app.py", line 1832, in full_dispatch_request
    rv = self.dispatch_request()
  File "/usr/local/lib/python2.7/dist-packages/flask/app.py", line 1818, in dispatch_request
    return self.view_functions[rule.endpoint](**req.view_args)
  File "/home/vuns/Desktop/flask-project-master/app/api/chicken_farm_control.py", line 51, in feeding
    control_feeding(status)
  File "/home/vuns/Desktop/flask-project-master/app/utils/farm_control.py", line 14, in control_feeding
    publish.single(current_app.config['FEEDING_TOPIC'], '0', hostname=current_app.config['MQT_SERVER'])
  File "/usr/local/lib/python2.7/dist-packages/paho/mqtt/publish.py", line 223, in single
    protocol, transport)
  File "/usr/local/lib/python2.7/dist-packages/paho/mqtt/publish.py", line 159, in multiple
    client.connect(hostname, port, keepalive)
  File "/usr/local/lib/python2.7/dist-packages/paho/mqtt/client.py", line 839, in connect
    return self.reconnect()
  File "/usr/local/lib/python2.7/dist-packages/paho/mqtt/client.py", line 962, in reconnect
    sock = socket.create_connection((self._host, self._port), source_address=(self._bind_address, 0))
  File "/usr/lib/python2.7/socket.py", line 575, in create_connection
    raise err
error: [Errno 111] Connection refused
2019-06-05 03:56:03,744 ERROR: HTTP_STATUS_CODE_500: {'message': 'Internal Server Error.', 'code': 500} [in api_error_handler:/home/vuns/Desktop/flask-project-master/app/exception.py:191]
Traceback (most recent call last):
  File "/usr/local/lib/python2.7/dist-packages/flask/app.py", line 1832, in full_dispatch_request
    rv = self.dispatch_request()
  File "/usr/local/lib/python2.7/dist-packages/flask/app.py", line 1818, in dispatch_request
    return self.view_functions[rule.endpoint](**req.view_args)
  File "/home/vuns/Desktop/flask-project-master/app/api/chicken_farm_control.py", line 51, in feeding
    control_feeding(status)
  File "/home/vuns/Desktop/flask-project-master/app/utils/farm_control.py", line 14, in control_feeding
    publish.single(current_app.config['FEEDING_TOPIC'], '0', hostname=current_app.config['MQT_SERVER'])
  File "/usr/local/lib/python2.7/dist-packages/paho/mqtt/publish.py", line 223, in single
    protocol, transport)
  File "/usr/local/lib/python2.7/dist-packages/paho/mqtt/publish.py", line 159, in multiple
    client.connect(hostname, port, keepalive)
  File "/usr/local/lib/python2.7/dist-packages/paho/mqtt/client.py", line 839, in connect
    return self.reconnect()
  File "/usr/local/lib/python2.7/dist-packages/paho/mqtt/client.py", line 962, in reconnect
    sock = socket.create_connection((self._host, self._port), source_address=(self._bind_address, 0))
  File "/usr/lib/python2.7/socket.py", line 575, in create_connection
    raise err
error: [Errno 111] Connection refused
2019-06-05 03:57:03,608 INFO: Config filename: app/config.py [in config_log_handler:/home/vuns/Desktop/flask-project-master/app/app.py:103]
2019-06-05 03:57:03,610 INFO: App log folder: /home/vuns/Desktop/flask-project-master/app/logs [in config_log_handler:/home/vuns/Desktop/flask-project-master/app/app.py:104]
2019-06-05 03:57:38,578 ERROR: HTTP_STATUS_CODE_500: {'message': 'Internal Server Error.', 'code': 500} [in api_error_handler:/home/vuns/Desktop/flask-project-master/app/exception.py:191]
Traceback (most recent call last):
  File "/usr/local/lib/python2.7/dist-packages/flask/app.py", line 1832, in full_dispatch_request
    rv = self.dispatch_request()
  File "/usr/local/lib/python2.7/dist-packages/flask/app.py", line 1818, in dispatch_request
    return self.view_functions[rule.endpoint](**req.view_args)
  File "/home/vuns/Desktop/flask-project-master/app/api/chicken_farm_control.py", line 20, in get_all_settings
    settings = list(settings)
  File "/usr/local/lib/python2.7/dist-packages/pymongo/cursor.py", line 1225, in next
    if len(self.__data) or self._refresh():
  File "/usr/local/lib/python2.7/dist-packages/pymongo/cursor.py", line 1117, in _refresh
    self.__session = self.__collection.database.client._ensure_session()
  File "/usr/local/lib/python2.7/dist-packages/pymongo/mongo_client.py", line 1598, in _ensure_session
    return self.__start_session(True, causal_consistency=False)
  File "/usr/local/lib/python2.7/dist-packages/pymongo/mongo_client.py", line 1551, in __start_session
    server_session = self._get_server_session()
  File "/usr/local/lib/python2.7/dist-packages/pymongo/mongo_client.py", line 1584, in _get_server_session
    return self._topology.get_server_session()
  File "/usr/local/lib/python2.7/dist-packages/pymongo/topology.py", line 429, in get_server_session
    None)
  File "/usr/local/lib/python2.7/dist-packages/pymongo/topology.py", line 200, in _select_servers_loop
    self._error_message(selector))
ServerSelectionTimeoutError: 45.77.47.66:27017: timed out
2019-06-05 03:57:38,578 ERROR: HTTP_STATUS_CODE_500: {'message': 'Internal Server Error.', 'code': 500} [in api_error_handler:/home/vuns/Desktop/flask-project-master/app/exception.py:191]
Traceback (most recent call last):
  File "/usr/local/lib/python2.7/dist-packages/flask/app.py", line 1832, in full_dispatch_request
    rv = self.dispatch_request()
  File "/usr/local/lib/python2.7/dist-packages/flask/app.py", line 1818, in dispatch_request
    return self.view_functions[rule.endpoint](**req.view_args)
  File "/home/vuns/Desktop/flask-project-master/app/api/chicken_farm_control.py", line 20, in get_all_settings
    settings = list(settings)
  File "/usr/local/lib/python2.7/dist-packages/pymongo/cursor.py", line 1225, in next
    if len(self.__data) or self._refresh():
  File "/usr/local/lib/python2.7/dist-packages/pymongo/cursor.py", line 1117, in _refresh
    self.__session = self.__collection.database.client._ensure_session()
  File "/usr/local/lib/python2.7/dist-packages/pymongo/mongo_client.py", line 1598, in _ensure_session
    return self.__start_session(True, causal_consistency=False)
  File "/usr/local/lib/python2.7/dist-packages/pymongo/mongo_client.py", line 1551, in __start_session
    server_session = self._get_server_session()
  File "/usr/local/lib/python2.7/dist-packages/pymongo/mongo_client.py", line 1584, in _get_server_session
    return self._topology.get_server_session()
  File "/usr/local/lib/python2.7/dist-packages/pymongo/topology.py", line 429, in get_server_session
    None)
  File "/usr/local/lib/python2.7/dist-packages/pymongo/topology.py", line 200, in _select_servers_loop
    self._error_message(selector))
ServerSelectionTimeoutError: 45.77.47.66:27017: timed out
2019-06-05 03:58:05,287 INFO: Config filename: app/config.py [in config_log_handler:/home/vuns/Desktop/flask-project-master/app/app.py:103]
2019-06-05 03:58:05,289 INFO: App log folder: /home/vuns/Desktop/flask-project-master/app/logs [in config_log_handler:/home/vuns/Desktop/flask-project-master/app/app.py:104]
2019-06-05 03:58:40,917 ERROR: HTTP_STATUS_CODE_500: {'message': 'Internal Server Error.', 'code': 500} [in api_error_handler:/home/vuns/Desktop/flask-project-master/app/exception.py:191]
Traceback (most recent call last):
  File "/usr/local/lib/python2.7/dist-packages/flask/app.py", line 1832, in full_dispatch_request
    rv = self.dispatch_request()
  File "/usr/local/lib/python2.7/dist-packages/flask/app.py", line 1818, in dispatch_request
    return self.view_functions[rule.endpoint](**req.view_args)
  File "/home/vuns/Desktop/flask-project-master/app/api/chicken_farm_control.py", line 20, in get_all_settings
    settings = list(settings)
  File "/usr/local/lib/python2.7/dist-packages/pymongo/cursor.py", line 1225, in next
    if len(self.__data) or self._refresh():
  File "/usr/local/lib/python2.7/dist-packages/pymongo/cursor.py", line 1117, in _refresh
    self.__session = self.__collection.database.client._ensure_session()
  File "/usr/local/lib/python2.7/dist-packages/pymongo/mongo_client.py", line 1598, in _ensure_session
    return self.__start_session(True, causal_consistency=False)
  File "/usr/local/lib/python2.7/dist-packages/pymongo/mongo_client.py", line 1551, in __start_session
    server_session = self._get_server_session()
  File "/usr/local/lib/python2.7/dist-packages/pymongo/mongo_client.py", line 1584, in _get_server_session
    return self._topology.get_server_session()
  File "/usr/local/lib/python2.7/dist-packages/pymongo/topology.py", line 429, in get_server_session
    None)
  File "/usr/local/lib/python2.7/dist-packages/pymongo/topology.py", line 200, in _select_servers_loop
    self._error_message(selector))
ServerSelectionTimeoutError: 45.77.47.66:27017: timed out
2019-06-05 03:58:40,917 ERROR: HTTP_STATUS_CODE_500: {'message': 'Internal Server Error.', 'code': 500} [in api_error_handler:/home/vuns/Desktop/flask-project-master/app/exception.py:191]
Traceback (most recent call last):
  File "/usr/local/lib/python2.7/dist-packages/flask/app.py", line 1832, in full_dispatch_request
    rv = self.dispatch_request()
  File "/usr/local/lib/python2.7/dist-packages/flask/app.py", line 1818, in dispatch_request
    return self.view_functions[rule.endpoint](**req.view_args)
  File "/home/vuns/Desktop/flask-project-master/app/api/chicken_farm_control.py", line 20, in get_all_settings
    settings = list(settings)
  File "/usr/local/lib/python2.7/dist-packages/pymongo/cursor.py", line 1225, in next
    if len(self.__data) or self._refresh():
  File "/usr/local/lib/python2.7/dist-packages/pymongo/cursor.py", line 1117, in _refresh
    self.__session = self.__collection.database.client._ensure_session()
  File "/usr/local/lib/python2.7/dist-packages/pymongo/mongo_client.py", line 1598, in _ensure_session
    return self.__start_session(True, causal_consistency=False)
  File "/usr/local/lib/python2.7/dist-packages/pymongo/mongo_client.py", line 1551, in __start_session
    server_session = self._get_server_session()
  File "/usr/local/lib/python2.7/dist-packages/pymongo/mongo_client.py", line 1584, in _get_server_session
    return self._topology.get_server_session()
  File "/usr/local/lib/python2.7/dist-packages/pymongo/topology.py", line 429, in get_server_session
    None)
  File "/usr/local/lib/python2.7/dist-packages/pymongo/topology.py", line 200, in _select_servers_loop
    self._error_message(selector))
ServerSelectionTimeoutError: 45.77.47.66:27017: timed out
2019-06-05 04:08:15,064 INFO: Config filename: app/config.py [in config_log_handler:/home/vuns/Desktop/flask-project-master/app/app.py:103]
2019-06-05 04:08:15,085 INFO: App log folder: /home/vuns/Desktop/flask-project-master/app/logs [in config_log_handler:/home/vuns/Desktop/flask-project-master/app/app.py:104]
2019-06-05 04:08:40,351 INFO: Config filename: app/config.py [in config_log_handler:/home/vuns/Desktop/flask-project-master/app/app.py:103]
2019-06-05 04:08:40,353 INFO: App log folder: /home/vuns/Desktop/flask-project-master/app/logs [in config_log_handler:/home/vuns/Desktop/flask-project-master/app/app.py:104]
2019-06-05 04:09:18,965 ERROR: HTTP_STATUS_CODE_500: {'message': 'Internal Server Error.', 'code': 500} [in api_error_handler:/home/vuns/Desktop/flask-project-master/app/exception.py:191]
Traceback (most recent call last):
  File "/usr/local/lib/python2.7/dist-packages/flask/app.py", line 1832, in full_dispatch_request
    rv = self.dispatch_request()
  File "/usr/local/lib/python2.7/dist-packages/flask/app.py", line 1818, in dispatch_request
    return self.view_functions[rule.endpoint](**req.view_args)
  File "/home/vuns/Desktop/flask-project-master/app/api/chicken_farm_control.py", line 20, in get_all_settings
    settings = list(settings)
  File "/usr/local/lib/python2.7/dist-packages/pymongo/cursor.py", line 1225, in next
    if len(self.__data) or self._refresh():
  File "/usr/local/lib/python2.7/dist-packages/pymongo/cursor.py", line 1117, in _refresh
    self.__session = self.__collection.database.client._ensure_session()
  File "/usr/local/lib/python2.7/dist-packages/pymongo/mongo_client.py", line 1598, in _ensure_session
    return self.__start_session(True, causal_consistency=False)
  File "/usr/local/lib/python2.7/dist-packages/pymongo/mongo_client.py", line 1551, in __start_session
    server_session = self._get_server_session()
  File "/usr/local/lib/python2.7/dist-packages/pymongo/mongo_client.py", line 1584, in _get_server_session
    return self._topology.get_server_session()
  File "/usr/local/lib/python2.7/dist-packages/pymongo/topology.py", line 429, in get_server_session
    None)
  File "/usr/local/lib/python2.7/dist-packages/pymongo/topology.py", line 200, in _select_servers_loop
    self._error_message(selector))
ServerSelectionTimeoutError: 45.77.47.66:27017: timed out
2019-06-05 04:09:18,965 ERROR: HTTP_STATUS_CODE_500: {'message': 'Internal Server Error.', 'code': 500} [in api_error_handler:/home/vuns/Desktop/flask-project-master/app/exception.py:191]
Traceback (most recent call last):
  File "/usr/local/lib/python2.7/dist-packages/flask/app.py", line 1832, in full_dispatch_request
    rv = self.dispatch_request()
  File "/usr/local/lib/python2.7/dist-packages/flask/app.py", line 1818, in dispatch_request
    return self.view_functions[rule.endpoint](**req.view_args)
  File "/home/vuns/Desktop/flask-project-master/app/api/chicken_farm_control.py", line 20, in get_all_settings
    settings = list(settings)
  File "/usr/local/lib/python2.7/dist-packages/pymongo/cursor.py", line 1225, in next
    if len(self.__data) or self._refresh():
  File "/usr/local/lib/python2.7/dist-packages/pymongo/cursor.py", line 1117, in _refresh
    self.__session = self.__collection.database.client._ensure_session()
  File "/usr/local/lib/python2.7/dist-packages/pymongo/mongo_client.py", line 1598, in _ensure_session
    return self.__start_session(True, causal_consistency=False)
  File "/usr/local/lib/python2.7/dist-packages/pymongo/mongo_client.py", line 1551, in __start_session
    server_session = self._get_server_session()
  File "/usr/local/lib/python2.7/dist-packages/pymongo/mongo_client.py", line 1584, in _get_server_session
    return self._topology.get_server_session()
  File "/usr/local/lib/python2.7/dist-packages/pymongo/topology.py", line 429, in get_server_session
    None)
  File "/usr/local/lib/python2.7/dist-packages/pymongo/topology.py", line 200, in _select_servers_loop
    self._error_message(selector))
ServerSelectionTimeoutError: 45.77.47.66:27017: timed out
2019-06-05 04:20:01,627 INFO: Config filename: app/config.py [in config_log_handler:/home/vuns/Desktop/flask-project-master/app/app.py:103]
2019-06-05 04:20:01,628 INFO: App log folder: /home/vuns/Desktop/flask-project-master/app/logs [in config_log_handler:/home/vuns/Desktop/flask-project-master/app/app.py:104]
2019-06-05 04:50:49,503 ERROR: HTTP_STATUS_CODE_500: {'message': 'Internal Server Error.', 'code': 500} [in api_error_handler:/home/vuns/Desktop/flask-project-master/app/exception.py:191]
Traceback (most recent call last):
  File "/usr/local/lib/python2.7/dist-packages/flask/app.py", line 1832, in full_dispatch_request
    rv = self.dispatch_request()
  File "/usr/local/lib/python2.7/dist-packages/flask/app.py", line 1818, in dispatch_request
    return self.view_functions[rule.endpoint](**req.view_args)
  File "/home/vuns/Desktop/flask-project-master/app/api/chicken_farm_control.py", line 51, in feeding
    control_feeding(status)
  File "/home/vuns/Desktop/flask-project-master/app/utils/farm_control.py", line 12, in control_feeding
    publish.single(current_app.config['FEEDING_TOPIC'], '1', hostname=current_app.config['MQT_SERVER'])
  File "/usr/local/lib/python2.7/dist-packages/paho/mqtt/publish.py", line 223, in single
    protocol, transport)
  File "/usr/local/lib/python2.7/dist-packages/paho/mqtt/publish.py", line 159, in multiple
    client.connect(hostname, port, keepalive)
  File "/usr/local/lib/python2.7/dist-packages/paho/mqtt/client.py", line 839, in connect
    return self.reconnect()
  File "/usr/local/lib/python2.7/dist-packages/paho/mqtt/client.py", line 962, in reconnect
    sock = socket.create_connection((self._host, self._port), source_address=(self._bind_address, 0))
  File "/usr/lib/python2.7/socket.py", line 575, in create_connection
    raise err
error: [Errno 111] Connection refused
2019-06-05 04:50:49,503 ERROR: HTTP_STATUS_CODE_500: {'message': 'Internal Server Error.', 'code': 500} [in api_error_handler:/home/vuns/Desktop/flask-project-master/app/exception.py:191]
Traceback (most recent call last):
  File "/usr/local/lib/python2.7/dist-packages/flask/app.py", line 1832, in full_dispatch_request
    rv = self.dispatch_request()
  File "/usr/local/lib/python2.7/dist-packages/flask/app.py", line 1818, in dispatch_request
    return self.view_functions[rule.endpoint](**req.view_args)
  File "/home/vuns/Desktop/flask-project-master/app/api/chicken_farm_control.py", line 51, in feeding
    control_feeding(status)
  File "/home/vuns/Desktop/flask-project-master/app/utils/farm_control.py", line 12, in control_feeding
    publish.single(current_app.config['FEEDING_TOPIC'], '1', hostname=current_app.config['MQT_SERVER'])
  File "/usr/local/lib/python2.7/dist-packages/paho/mqtt/publish.py", line 223, in single
    protocol, transport)
  File "/usr/local/lib/python2.7/dist-packages/paho/mqtt/publish.py", line 159, in multiple
    client.connect(hostname, port, keepalive)
  File "/usr/local/lib/python2.7/dist-packages/paho/mqtt/client.py", line 839, in connect
    return self.reconnect()
  File "/usr/local/lib/python2.7/dist-packages/paho/mqtt/client.py", line 962, in reconnect
    sock = socket.create_connection((self._host, self._port), source_address=(self._bind_address, 0))
  File "/usr/lib/python2.7/socket.py", line 575, in create_connection
    raise err
error: [Errno 111] Connection refused
2019-06-05 06:12:13,032 INFO: Config filename: app/config.py [in config_log_handler:/home/vuns/Desktop/flask-project-master/app/app.py:103]
2019-06-05 06:12:13,035 INFO: App log folder: /home/vuns/Desktop/flask-project-master/app/logs [in config_log_handler:/home/vuns/Desktop/flask-project-master/app/app.py:104]
2019-06-05 06:33:30,416 INFO: Config filename: app/config.py [in config_log_handler:/home/vuns/Desktop/flask-project-master/app/app.py:103]
2019-06-05 06:33:30,418 INFO: App log folder: /home/vuns/Desktop/flask-project-master/app/logs [in config_log_handler:/home/vuns/Desktop/flask-project-master/app/app.py:104]
2019-06-05 06:35:06,514 INFO: Config filename: app/config.py [in config_log_handler:/home/vuns/Desktop/flask-project-master/app/app.py:103]
2019-06-05 06:35:06,515 INFO: App log folder: /home/vuns/Desktop/flask-project-master/app/logs [in config_log_handler:/home/vuns/Desktop/flask-project-master/app/app.py:104]
2019-06-05 06:38:26,194 INFO: Config filename: app/config.py [in config_log_handler:/home/vuns/Desktop/flask-project-master/app/app.py:103]
2019-06-05 06:38:26,195 INFO: App log folder: /home/vuns/Desktop/flask-project-master/app/logs [in config_log_handler:/home/vuns/Desktop/flask-project-master/app/app.py:104]
2019-06-05 06:41:13,931 INFO: Config filename: app/config.py [in config_log_handler:/home/vuns/Desktop/flask-project-master/app/app.py:103]
2019-06-05 06:41:13,932 INFO: App log folder: /home/vuns/Desktop/flask-project-master/app/logs [in config_log_handler:/home/vuns/Desktop/flask-project-master/app/app.py:104]
2019-06-05 06:44:15,176 INFO: Config filename: app/config.py [in config_log_handler:/home/vuns/Desktop/flask-project-master/app/app.py:103]
2019-06-05 06:44:15,177 INFO: App log folder: /home/vuns/Desktop/flask-project-master/app/logs [in config_log_handler:/home/vuns/Desktop/flask-project-master/app/app.py:104]
2019-06-05 06:45:32,867 INFO: Config filename: app/config.py [in config_log_handler:/home/vuns/Desktop/flask-project-master/app/app.py:103]
2019-06-05 06:45:32,868 INFO: App log folder: /home/vuns/Desktop/flask-project-master/app/logs [in config_log_handler:/home/vuns/Desktop/flask-project-master/app/app.py:104]
2019-06-05 06:46:08,068 INFO: Config filename: app/config.py [in config_log_handler:/home/vuns/Desktop/flask-project-master/app/app.py:103]
2019-06-05 06:46:08,070 INFO: App log folder: /home/vuns/Desktop/flask-project-master/app/logs [in config_log_handler:/home/vuns/Desktop/flask-project-master/app/app.py:104]
2019-06-05 06:48:23,301 INFO: Config filename: app/config.py [in config_log_handler:/home/vuns/Desktop/flask-project-master/app/app.py:103]
2019-06-05 06:48:23,302 INFO: App log folder: /home/vuns/Desktop/flask-project-master/app/logs [in config_log_handler:/home/vuns/Desktop/flask-project-master/app/app.py:104]
2019-06-05 06:50:47,232 INFO: Config filename: app/config.py [in config_log_handler:/home/vuns/Desktop/flask-project-master/app/app.py:103]
2019-06-05 06:50:47,233 INFO: App log folder: /home/vuns/Desktop/flask-project-master/app/logs [in config_log_handler:/home/vuns/Desktop/flask-project-master/app/app.py:104]
2019-06-05 06:51:24,059 INFO: Config filename: app/config.py [in config_log_handler:/home/vuns/Desktop/flask-project-master/app/app.py:103]
2019-06-05 06:51:24,061 INFO: App log folder: /home/vuns/Desktop/flask-project-master/app/logs [in config_log_handler:/home/vuns/Desktop/flask-project-master/app/app.py:104]
2019-06-05 08:14:15,529 INFO: Config filename: app/config.py [in config_log_handler:/home/vuns/Desktop/flask-project-master/app/app.py:103]
2019-06-05 08:14:15,530 INFO: App log folder: /home/vuns/Desktop/flask-project-master/app/logs [in config_log_handler:/home/vuns/Desktop/flask-project-master/app/app.py:104]
2019-06-05 08:14:27,722 ERROR: HTTP_STATUS_CODE_500: {'message': 'Internal Server Error.', 'code': 500} [in api_error_handler:/home/vuns/Desktop/flask-project-master/app/exception.py:191]
Traceback (most recent call last):
  File "/usr/local/lib/python2.7/dist-packages/flask/app.py", line 1832, in full_dispatch_request
    rv = self.dispatch_request()
  File "/usr/local/lib/python2.7/dist-packages/flask/app.py", line 1818, in dispatch_request
    return self.view_functions[rule.endpoint](**req.view_args)
  File "/home/vuns/Desktop/flask-project-master/app/api/chicken_farm_control.py", line 37, in setting
    pair_id = time.time()
AttributeError: type object 'datetime.time' has no attribute 'time'
2019-06-05 08:14:27,722 ERROR: HTTP_STATUS_CODE_500: {'message': 'Internal Server Error.', 'code': 500} [in api_error_handler:/home/vuns/Desktop/flask-project-master/app/exception.py:191]
Traceback (most recent call last):
  File "/usr/local/lib/python2.7/dist-packages/flask/app.py", line 1832, in full_dispatch_request
    rv = self.dispatch_request()
  File "/usr/local/lib/python2.7/dist-packages/flask/app.py", line 1818, in dispatch_request
    return self.view_functions[rule.endpoint](**req.view_args)
  File "/home/vuns/Desktop/flask-project-master/app/api/chicken_farm_control.py", line 37, in setting
    pair_id = time.time()
AttributeError: type object 'datetime.time' has no attribute 'time'
2019-06-05 08:16:59,854 INFO: Config filename: app/config.py [in config_log_handler:/home/vuns/Desktop/flask-project-master/app/app.py:103]
2019-06-05 08:16:59,856 INFO: App log folder: /home/vuns/Desktop/flask-project-master/app/logs [in config_log_handler:/home/vuns/Desktop/flask-project-master/app/app.py:104]
2019-06-05 08:17:06,981 ERROR: HTTP_STATUS_CODE_500: {'message': 'Internal Server Error.', 'code': 500} [in api_error_handler:/home/vuns/Desktop/flask-project-master/app/exception.py:191]
Traceback (most recent call last):
  File "/usr/local/lib/python2.7/dist-packages/flask/app.py", line 1832, in full_dispatch_request
    rv = self.dispatch_request()
  File "/usr/local/lib/python2.7/dist-packages/flask/app.py", line 1818, in dispatch_request
    return self.view_functions[rule.endpoint](**req.view_args)
  File "/home/vuns/Desktop/flask-project-master/app/api/chicken_farm_control.py", line 47, in setting
    settings_collection.insert(**open_config)
  File "/home/vuns/Desktop/flask-project-master/app/db/mongo.py", line 26, in insert
    return self.db.insert(doc)
  File "/usr/local/lib/python2.7/dist-packages/pymongo/collection.py", line 3195, in insert
    check_keys, manipulate, write_concern)
  File "/usr/local/lib/python2.7/dist-packages/pymongo/collection.py", line 614, in _insert
    bypass_doc_val, session)
  File "/usr/local/lib/python2.7/dist-packages/pymongo/collection.py", line 602, in _insert_one
    acknowledged, _insert_command, session)
  File "/usr/local/lib/python2.7/dist-packages/pymongo/mongo_client.py", line 1280, in _retryable_write
    return self._retry_with_session(retryable, func, s, None)
  File "/usr/local/lib/python2.7/dist-packages/pymongo/mongo_client.py", line 1233, in _retry_with_session
    return func(session, sock_info, retryable)
  File "/usr/local/lib/python2.7/dist-packages/pymongo/collection.py", line 597, in _insert_command
    retryable_write=retryable_write)
  File "/usr/local/lib/python2.7/dist-packages/pymongo/pool.py", line 589, in command
    self._raise_connection_failure(error)
  File "/usr/local/lib/python2.7/dist-packages/pymongo/pool.py", line 750, in _raise_connection_failure
    raise error
InvalidDocument: cannot encode object: datetime.time(5, 30), of type: <type 'datetime.time'>
2019-06-05 08:17:06,981 ERROR: HTTP_STATUS_CODE_500: {'message': 'Internal Server Error.', 'code': 500} [in api_error_handler:/home/vuns/Desktop/flask-project-master/app/exception.py:191]
Traceback (most recent call last):
  File "/usr/local/lib/python2.7/dist-packages/flask/app.py", line 1832, in full_dispatch_request
    rv = self.dispatch_request()
  File "/usr/local/lib/python2.7/dist-packages/flask/app.py", line 1818, in dispatch_request
    return self.view_functions[rule.endpoint](**req.view_args)
  File "/home/vuns/Desktop/flask-project-master/app/api/chicken_farm_control.py", line 47, in setting
    settings_collection.insert(**open_config)
  File "/home/vuns/Desktop/flask-project-master/app/db/mongo.py", line 26, in insert
    return self.db.insert(doc)
  File "/usr/local/lib/python2.7/dist-packages/pymongo/collection.py", line 3195, in insert
    check_keys, manipulate, write_concern)
  File "/usr/local/lib/python2.7/dist-packages/pymongo/collection.py", line 614, in _insert
    bypass_doc_val, session)
  File "/usr/local/lib/python2.7/dist-packages/pymongo/collection.py", line 602, in _insert_one
    acknowledged, _insert_command, session)
  File "/usr/local/lib/python2.7/dist-packages/pymongo/mongo_client.py", line 1280, in _retryable_write
    return self._retry_with_session(retryable, func, s, None)
  File "/usr/local/lib/python2.7/dist-packages/pymongo/mongo_client.py", line 1233, in _retry_with_session
    return func(session, sock_info, retryable)
  File "/usr/local/lib/python2.7/dist-packages/pymongo/collection.py", line 597, in _insert_command
    retryable_write=retryable_write)
  File "/usr/local/lib/python2.7/dist-packages/pymongo/pool.py", line 589, in command
    self._raise_connection_failure(error)
  File "/usr/local/lib/python2.7/dist-packages/pymongo/pool.py", line 750, in _raise_connection_failure
    raise error
InvalidDocument: cannot encode object: datetime.time(5, 30), of type: <type 'datetime.time'>
2019-06-05 08:18:38,969 INFO: Config filename: app/config.py [in config_log_handler:/home/vuns/Desktop/flask-project-master/app/app.py:103]
2019-06-05 08:18:38,970 INFO: App log folder: /home/vuns/Desktop/flask-project-master/app/logs [in config_log_handler:/home/vuns/Desktop/flask-project-master/app/app.py:104]
2019-06-05 08:28:11,028 INFO: Config filename: app/config.py [in config_log_handler:/home/vuns/Desktop/flask-project-master/app/app.py:103]
2019-06-05 08:28:11,030 INFO: App log folder: /home/vuns/Desktop/flask-project-master/app/logs [in config_log_handler:/home/vuns/Desktop/flask-project-master/app/app.py:104]
2019-06-05 08:30:07,091 INFO: Config filename: app/config.py [in config_log_handler:/home/vuns/Desktop/flask-project-master/app/app.py:103]
2019-06-05 08:30:07,093 INFO: App log folder: /home/vuns/Desktop/flask-project-master/app/logs [in config_log_handler:/home/vuns/Desktop/flask-project-master/app/app.py:104]
2019-06-05 08:30:43,478 INFO: Config filename: app/config.py [in config_log_handler:/home/vuns/Desktop/flask-project-master/app/app.py:103]
2019-06-05 08:30:43,479 INFO: App log folder: /home/vuns/Desktop/flask-project-master/app/logs [in config_log_handler:/home/vuns/Desktop/flask-project-master/app/app.py:104]
2019-06-05 08:31:59,120 INFO: Config filename: app/config.py [in config_log_handler:/home/vuns/Desktop/flask-project-master/app/app.py:103]
2019-06-05 08:31:59,121 INFO: App log folder: /home/vuns/Desktop/flask-project-master/app/logs [in config_log_handler:/home/vuns/Desktop/flask-project-master/app/app.py:104]
2019-06-05 08:35:04,364 INFO: Config filename: app/config.py [in config_log_handler:/home/vuns/Desktop/flask-project-master/app/app.py:103]
2019-06-05 08:35:04,365 INFO: App log folder: /home/vuns/Desktop/flask-project-master/app/logs [in config_log_handler:/home/vuns/Desktop/flask-project-master/app/app.py:104]
2019-06-05 08:35:58,342 INFO: Config filename: app/config.py [in config_log_handler:/home/vuns/Desktop/flask-project-master/app/app.py:103]
2019-06-05 08:35:58,344 INFO: App log folder: /home/vuns/Desktop/flask-project-master/app/logs [in config_log_handler:/home/vuns/Desktop/flask-project-master/app/app.py:104]
2019-06-05 08:44:12,316 INFO: Config filename: app/config.py [in config_log_handler:/home/vuns/Desktop/flask-project-master/app/app.py:103]
2019-06-05 08:44:12,317 INFO: App log folder: /home/vuns/Desktop/flask-project-master/app/logs [in config_log_handler:/home/vuns/Desktop/flask-project-master/app/app.py:104]
2019-06-05 08:50:49,654 INFO: Config filename: app/config.py [in config_log_handler:/home/vuns/Desktop/flask-project-master/app/app.py:103]
2019-06-05 08:50:49,693 INFO: App log folder: /home/vuns/Desktop/flask-project-master/app/logs [in config_log_handler:/home/vuns/Desktop/flask-project-master/app/app.py:104]
2019-06-05 08:52:52,695 INFO: Config filename: app/config.py [in config_log_handler:/home/vuns/Desktop/flask-project-master/app/app.py:103]
2019-06-05 08:52:52,697 INFO: App log folder: /home/vuns/Desktop/flask-project-master/app/logs [in config_log_handler:/home/vuns/Desktop/flask-project-master/app/app.py:104]
2019-06-05 08:55:54,758 INFO: Config filename: app/config.py [in config_log_handler:/home/vuns/Desktop/flask-project-master/app/app.py:103]
2019-06-05 08:55:54,759 INFO: App log folder: /home/vuns/Desktop/flask-project-master/app/logs [in config_log_handler:/home/vuns/Desktop/flask-project-master/app/app.py:104]
2019-06-05 08:57:09,623 INFO: Config filename: app/config.py [in config_log_handler:/home/vuns/Desktop/flask-project-master/app/app.py:103]
2019-06-05 08:57:09,625 INFO: App log folder: /home/vuns/Desktop/flask-project-master/app/logs [in config_log_handler:/home/vuns/Desktop/flask-project-master/app/app.py:104]
2019-06-05 09:01:12,580 INFO: Config filename: app/config.py [in config_log_handler:/home/vuns/Desktop/flask-project-master/app/app.py:103]
2019-06-05 09:01:12,581 INFO: App log folder: /home/vuns/Desktop/flask-project-master/app/logs [in config_log_handler:/home/vuns/Desktop/flask-project-master/app/app.py:104]
2019-06-05 09:06:25,447 INFO: Config filename: app/config.py [in config_log_handler:/home/vuns/Desktop/flask-project-master/app/app.py:103]
2019-06-05 09:06:25,449 INFO: App log folder: /home/vuns/Desktop/flask-project-master/app/logs [in config_log_handler:/home/vuns/Desktop/flask-project-master/app/app.py:104]
2019-06-05 09:09:31,082 INFO: Config filename: app/config.py [in config_log_handler:/home/vuns/Desktop/flask-project-master/app/app.py:103]
2019-06-05 09:09:31,083 INFO: App log folder: /home/vuns/Desktop/flask-project-master/app/logs [in config_log_handler:/home/vuns/Desktop/flask-project-master/app/app.py:104]
2019-06-05 09:16:43,970 INFO: Config filename: app/config.py [in config_log_handler:/home/vuns/Desktop/flask-project-master/app/app.py:103]
2019-06-05 09:16:43,972 INFO: App log folder: /home/vuns/Desktop/flask-project-master/app/logs [in config_log_handler:/home/vuns/Desktop/flask-project-master/app/app.py:104]
2019-06-05 09:20:24,353 INFO: Config filename: app/config.py [in config_log_handler:/home/vuns/Desktop/flask-project-master/app/app.py:103]
2019-06-05 09:20:24,354 INFO: App log folder: /home/vuns/Desktop/flask-project-master/app/logs [in config_log_handler:/home/vuns/Desktop/flask-project-master/app/app.py:104]
2019-06-05 09:21:35,190 INFO: Config filename: app/config.py [in config_log_handler:/home/vuns/Desktop/flask-project-master/app/app.py:103]
2019-06-05 09:21:35,191 INFO: App log folder: /home/vuns/Desktop/flask-project-master/app/logs [in config_log_handler:/home/vuns/Desktop/flask-project-master/app/app.py:104]
2019-06-05 09:22:37,264 INFO: Config filename: app/config.py [in config_log_handler:/home/vuns/Desktop/flask-project-master/app/app.py:103]
2019-06-05 09:22:37,303 INFO: App log folder: /home/vuns/Desktop/flask-project-master/app/logs [in config_log_handler:/home/vuns/Desktop/flask-project-master/app/app.py:104]
2019-06-05 09:27:59,047 INFO: Config filename: app/config.py [in config_log_handler:/home/vuns/Desktop/flask-project-master/app/app.py:103]
2019-06-05 09:27:59,048 INFO: App log folder: /home/vuns/Desktop/flask-project-master/app/logs [in config_log_handler:/home/vuns/Desktop/flask-project-master/app/app.py:104]
2019-06-05 09:41:30,424 INFO: Config filename: app/config.py [in config_log_handler:/home/vuns/Desktop/flask-project-master/app/app.py:103]
2019-06-05 09:41:30,426 INFO: App log folder: /home/vuns/Desktop/flask-project-master/app/logs [in config_log_handler:/home/vuns/Desktop/flask-project-master/app/app.py:104]
2019-06-05 11:47:30,839 INFO: Config filename: app/config.py [in config_log_handler:/home/vuns/Desktop/flask-project-master/app/app.py:103]
2019-06-05 11:47:30,841 INFO: App log folder: /home/vuns/Desktop/flask-project-master/app/logs [in config_log_handler:/home/vuns/Desktop/flask-project-master/app/app.py:104]
2019-06-05 19:22:40,408 INFO: Config filename: app/config.py [in config_log_handler:/home/vuns/Desktop/flask-project-master/app/app.py:103]
2019-06-05 19:22:40,409 INFO: App log folder: /home/vuns/Desktop/flask-project-master/app/logs [in config_log_handler:/home/vuns/Desktop/flask-project-master/app/app.py:104]
2019-06-05 19:22:41,109 INFO: Config filename: app/config.py [in config_log_handler:/home/vuns/Desktop/flask-project-master/app/app.py:103]
2019-06-05 19:22:41,110 INFO: App log folder: /home/vuns/Desktop/flask-project-master/app/logs [in config_log_handler:/home/vuns/Desktop/flask-project-master/app/app.py:104]
2019-06-05 19:43:37,322 INFO: Config filename: app/config.py [in config_log_handler:/home/vuns/Desktop/flask-project-master/app/app.py:103]
2019-06-05 19:43:37,342 INFO: App log folder: /home/vuns/Desktop/flask-project-master/app/logs [in config_log_handler:/home/vuns/Desktop/flask-project-master/app/app.py:104]
2019-06-05 19:44:35,025 INFO: Config filename: app/config.py [in config_log_handler:/home/vuns/Desktop/flask-project-master/app/app.py:103]
2019-06-05 19:44:35,027 INFO: App log folder: /home/vuns/Desktop/flask-project-master/app/logs [in config_log_handler:/home/vuns/Desktop/flask-project-master/app/app.py:104]
2019-06-05 19:44:36,958 INFO: Config filename: app/config.py [in config_log_handler:/home/vuns/Desktop/flask-project-master/app/app.py:103]
2019-06-05 19:44:36,959 INFO: App log folder: /home/vuns/Desktop/flask-project-master/app/logs [in config_log_handler:/home/vuns/Desktop/flask-project-master/app/app.py:104]
2019-06-05 19:55:37,762 INFO: Config filename: app/config.py [in config_log_handler:/home/vuns/Desktop/flask-project-master/app/app.py:103]
2019-06-05 19:55:37,764 INFO: App log folder: /home/vuns/Desktop/flask-project-master/app/logs [in config_log_handler:/home/vuns/Desktop/flask-project-master/app/app.py:104]
2019-06-05 19:55:39,598 INFO: Config filename: app/config.py [in config_log_handler:/home/vuns/Desktop/flask-project-master/app/app.py:103]
2019-06-05 19:55:39,599 INFO: App log folder: /home/vuns/Desktop/flask-project-master/app/logs [in config_log_handler:/home/vuns/Desktop/flask-project-master/app/app.py:104]
2019-06-05 19:56:03,855 INFO: Config filename: app/config.py [in config_log_handler:/home/vuns/Desktop/flask-project-master/app/app.py:103]
2019-06-05 19:56:03,857 INFO: App log folder: /home/vuns/Desktop/flask-project-master/app/logs [in config_log_handler:/home/vuns/Desktop/flask-project-master/app/app.py:104]
2019-06-05 19:56:05,590 INFO: Config filename: app/config.py [in config_log_handler:/home/vuns/Desktop/flask-project-master/app/app.py:103]
2019-06-05 19:56:05,592 INFO: App log folder: /home/vuns/Desktop/flask-project-master/app/logs [in config_log_handler:/home/vuns/Desktop/flask-project-master/app/app.py:104]
2019-06-05 20:02:48,156 INFO: Config filename: app/config.py [in config_log_handler:/home/vuns/Desktop/flask-project-master/app/app.py:103]
2019-06-05 20:02:48,157 INFO: App log folder: /home/vuns/Desktop/flask-project-master/app/logs [in config_log_handler:/home/vuns/Desktop/flask-project-master/app/app.py:104]
2019-06-05 20:02:49,845 INFO: Config filename: app/config.py [in config_log_handler:/home/vuns/Desktop/flask-project-master/app/app.py:103]
2019-06-05 20:02:49,846 INFO: App log folder: /home/vuns/Desktop/flask-project-master/app/logs [in config_log_handler:/home/vuns/Desktop/flask-project-master/app/app.py:104]
2019-06-05 20:03:20,550 INFO: Config filename: app/config.py [in config_log_handler:/home/vuns/Desktop/flask-project-master/app/app.py:103]
2019-06-05 20:03:20,553 INFO: App log folder: /home/vuns/Desktop/flask-project-master/app/logs [in config_log_handler:/home/vuns/Desktop/flask-project-master/app/app.py:104]
2019-06-05 20:03:22,372 INFO: Config filename: app/config.py [in config_log_handler:/home/vuns/Desktop/flask-project-master/app/app.py:103]
2019-06-05 20:03:22,374 INFO: App log folder: /home/vuns/Desktop/flask-project-master/app/logs [in config_log_handler:/home/vuns/Desktop/flask-project-master/app/app.py:104]
2019-06-05 20:03:25,042 ERROR: HTTP_STATUS_CODE_400: {'message': 'Bad Request.', 'code': 400} [in api_error_handler:/home/vuns/Desktop/flask-project-master/app/exception.py:191]
Traceback (most recent call last):
  File "/usr/local/lib/python2.7/dist-packages/flask/app.py", line 1832, in full_dispatch_request
    rv = self.dispatch_request()
  File "/usr/local/lib/python2.7/dist-packages/flask/app.py", line 1818, in dispatch_request
    return self.view_functions[rule.endpoint](**req.view_args)
  File "/home/vuns/Desktop/flask-project-master/app/api/chicken_farm_control.py", line 50, in setting
    args = parser.parse(params)
  File "/usr/local/lib/python2.7/dist-packages/webargs/core.py", line 363, in parse
    schema=schema, req=req, locations=locations or self.locations
  File "/usr/local/lib/python2.7/dist-packages/webargs/core.py", line 270, in _parse_request
    parsed_value = self.parse_arg(argname, field_obj, req, locations)
  File "/usr/local/lib/python2.7/dist-packages/webargs/core.py", line 242, in parse_arg
    value = self._get_value(name, field, req=req, location=location)
  File "/usr/local/lib/python2.7/dist-packages/webargs/core.py", line 218, in _get_value
    return function(req, name, argobj)
  File "/usr/local/lib/python2.7/dist-packages/webargs/flaskparser.py", line 74, in parse_json
    return self.handle_invalid_json_error(e, req)
  File "/usr/local/lib/python2.7/dist-packages/webargs/flaskparser.py", line 115, in handle_invalid_json_error
    abort(400, exc=error, messages={"json": ["Invalid JSON body."]})
  File "/usr/local/lib/python2.7/dist-packages/webargs/flaskparser.py", line 40, in abort
    raise err
BadRequest: 400 Bad Request: {'message': 'Bad Request.', 'code': 400}
2019-06-05 20:03:25,042 ERROR: HTTP_STATUS_CODE_400: {'message': 'Bad Request.', 'code': 400} [in api_error_handler:/home/vuns/Desktop/flask-project-master/app/exception.py:191]
Traceback (most recent call last):
  File "/usr/local/lib/python2.7/dist-packages/flask/app.py", line 1832, in full_dispatch_request
    rv = self.dispatch_request()
  File "/usr/local/lib/python2.7/dist-packages/flask/app.py", line 1818, in dispatch_request
    return self.view_functions[rule.endpoint](**req.view_args)
  File "/home/vuns/Desktop/flask-project-master/app/api/chicken_farm_control.py", line 50, in setting
    args = parser.parse(params)
  File "/usr/local/lib/python2.7/dist-packages/webargs/core.py", line 363, in parse
    schema=schema, req=req, locations=locations or self.locations
  File "/usr/local/lib/python2.7/dist-packages/webargs/core.py", line 270, in _parse_request
    parsed_value = self.parse_arg(argname, field_obj, req, locations)
  File "/usr/local/lib/python2.7/dist-packages/webargs/core.py", line 242, in parse_arg
    value = self._get_value(name, field, req=req, location=location)
  File "/usr/local/lib/python2.7/dist-packages/webargs/core.py", line 218, in _get_value
    return function(req, name, argobj)
  File "/usr/local/lib/python2.7/dist-packages/webargs/flaskparser.py", line 74, in parse_json
    return self.handle_invalid_json_error(e, req)
  File "/usr/local/lib/python2.7/dist-packages/webargs/flaskparser.py", line 115, in handle_invalid_json_error
    abort(400, exc=error, messages={"json": ["Invalid JSON body."]})
  File "/usr/local/lib/python2.7/dist-packages/webargs/flaskparser.py", line 40, in abort
    raise err
BadRequest: 400 Bad Request: {'message': 'Bad Request.', 'code': 400}
2019-06-05 20:03:28,072 ERROR: HTTP_STATUS_CODE_400: {'message': 'Bad Request.', 'code': 400} [in api_error_handler:/home/vuns/Desktop/flask-project-master/app/exception.py:191]
Traceback (most recent call last):
  File "/usr/local/lib/python2.7/dist-packages/flask/app.py", line 1832, in full_dispatch_request
    rv = self.dispatch_request()
  File "/usr/local/lib/python2.7/dist-packages/flask/app.py", line 1818, in dispatch_request
    return self.view_functions[rule.endpoint](**req.view_args)
  File "/home/vuns/Desktop/flask-project-master/app/api/chicken_farm_control.py", line 50, in setting
    args = parser.parse(params)
  File "/usr/local/lib/python2.7/dist-packages/webargs/core.py", line 363, in parse
    schema=schema, req=req, locations=locations or self.locations
  File "/usr/local/lib/python2.7/dist-packages/webargs/core.py", line 270, in _parse_request
    parsed_value = self.parse_arg(argname, field_obj, req, locations)
  File "/usr/local/lib/python2.7/dist-packages/webargs/core.py", line 242, in parse_arg
    value = self._get_value(name, field, req=req, location=location)
  File "/usr/local/lib/python2.7/dist-packages/webargs/core.py", line 218, in _get_value
    return function(req, name, argobj)
  File "/usr/local/lib/python2.7/dist-packages/webargs/flaskparser.py", line 74, in parse_json
    return self.handle_invalid_json_error(e, req)
  File "/usr/local/lib/python2.7/dist-packages/webargs/flaskparser.py", line 115, in handle_invalid_json_error
    abort(400, exc=error, messages={"json": ["Invalid JSON body."]})
  File "/usr/local/lib/python2.7/dist-packages/webargs/flaskparser.py", line 40, in abort
    raise err
BadRequest: 400 Bad Request: {'message': 'Bad Request.', 'code': 400}
2019-06-05 20:03:28,072 ERROR: HTTP_STATUS_CODE_400: {'message': 'Bad Request.', 'code': 400} [in api_error_handler:/home/vuns/Desktop/flask-project-master/app/exception.py:191]
Traceback (most recent call last):
  File "/usr/local/lib/python2.7/dist-packages/flask/app.py", line 1832, in full_dispatch_request
    rv = self.dispatch_request()
  File "/usr/local/lib/python2.7/dist-packages/flask/app.py", line 1818, in dispatch_request
    return self.view_functions[rule.endpoint](**req.view_args)
  File "/home/vuns/Desktop/flask-project-master/app/api/chicken_farm_control.py", line 50, in setting
    args = parser.parse(params)
  File "/usr/local/lib/python2.7/dist-packages/webargs/core.py", line 363, in parse
    schema=schema, req=req, locations=locations or self.locations
  File "/usr/local/lib/python2.7/dist-packages/webargs/core.py", line 270, in _parse_request
    parsed_value = self.parse_arg(argname, field_obj, req, locations)
  File "/usr/local/lib/python2.7/dist-packages/webargs/core.py", line 242, in parse_arg
    value = self._get_value(name, field, req=req, location=location)
  File "/usr/local/lib/python2.7/dist-packages/webargs/core.py", line 218, in _get_value
    return function(req, name, argobj)
  File "/usr/local/lib/python2.7/dist-packages/webargs/flaskparser.py", line 74, in parse_json
    return self.handle_invalid_json_error(e, req)
  File "/usr/local/lib/python2.7/dist-packages/webargs/flaskparser.py", line 115, in handle_invalid_json_error
    abort(400, exc=error, messages={"json": ["Invalid JSON body."]})
  File "/usr/local/lib/python2.7/dist-packages/webargs/flaskparser.py", line 40, in abort
    raise err
BadRequest: 400 Bad Request: {'message': 'Bad Request.', 'code': 400}
2019-06-05 20:14:02,049 INFO: Config filename: app/config.py [in config_log_handler:/home/vuns/Desktop/flask-project-master/app/app.py:103]
2019-06-05 20:14:02,051 INFO: App log folder: /home/vuns/Desktop/flask-project-master/app/logs [in config_log_handler:/home/vuns/Desktop/flask-project-master/app/app.py:104]
2019-06-05 20:14:03,827 INFO: Config filename: app/config.py [in config_log_handler:/home/vuns/Desktop/flask-project-master/app/app.py:103]
2019-06-05 20:14:03,828 INFO: App log folder: /home/vuns/Desktop/flask-project-master/app/logs [in config_log_handler:/home/vuns/Desktop/flask-project-master/app/app.py:104]
2019-06-05 20:20:33,904 INFO: Config filename: app/config.py [in config_log_handler:/home/vuns/Desktop/flask-project-master/app/app.py:103]
2019-06-05 20:20:33,906 INFO: App log folder: /home/vuns/Desktop/flask-project-master/app/logs [in config_log_handler:/home/vuns/Desktop/flask-project-master/app/app.py:104]
2019-06-05 20:20:35,720 INFO: Config filename: app/config.py [in config_log_handler:/home/vuns/Desktop/flask-project-master/app/app.py:103]
2019-06-05 20:20:35,722 INFO: App log folder: /home/vuns/Desktop/flask-project-master/app/logs [in config_log_handler:/home/vuns/Desktop/flask-project-master/app/app.py:104]
2019-06-05 20:23:15,051 INFO: Config filename: app/config.py [in config_log_handler:/home/vuns/Desktop/flask-project-master/app/app.py:103]
2019-06-05 20:23:15,052 INFO: App log folder: /home/vuns/Desktop/flask-project-master/app/logs [in config_log_handler:/home/vuns/Desktop/flask-project-master/app/app.py:104]
2019-06-05 20:25:17,544 INFO: Config filename: app/config.py [in config_log_handler:/home/vuns/Desktop/flask-project-master/app/app.py:103]
